Workbook

Sheet 3a Raw
A1: §3a · Raw descriptors — cross-section at month-end M (model inputs, pre-z-score)
A2: Month-end M | B2: 45626
A3: Worked name | B3: baba (Alibaba Group Holding Ltd)
A5: Position | B5: Ticker | C5: Beta | D5: Momentum | E5: Size | F5: Value | G5: Growth | H5: Leverage | I5: Liquidity | J5: ResidVol | K5: EarnYield | L5: NonLinSize | M5: mcap
A6: BBG000C2V3D6 | B6: a | C6: 0.87361464 | D6: 0.026554274 | E6: 24.391027 | F6: 0.13545564 | H6: 1.9852969 | I6: 19.248727 | J6: 0.23772176 | K6: 0.030895632 | L6: 14510.763 | M6: 3.9164113e+10
A7: BBG00B3T3HD3 | B7: aa | C7: 1.8033227 | D7: 0.51018529 | E7: 22.828019 | F7: 0.51809402 | H7: 3.4208422 | I7: 19.093715 | J7: 0.46853232 | K7: 0.010968822 | L7: 11896.101 | M7: 8.2050744e+09
A8: BBG005P7Q881 | B8: aal | C8: 1.4733478 | D8: 0.07803695 | E8: 22.978921 | F8: -0.57642672 | H8: -11.465091 | I8: 19.815722 | J8: 0.37523949 | K8: 0.084158302 | L8: 12133.578 | M8: 9.5415424e+09
A9: BBG00P2HLNY3 | B9: aami | C9: 1.060992 | D9: 0.51508679 | I9: 15.50743 | J9: 0.26056273
A10: BBG000D6VW15 | B10: aaoi | C10: 3.7852998 | D10: 0.17886792 | E10: 21.342833 | F10: 0.10036684 | H10: 2.198312 | I10: 18.075437 | J10: 1.08 | K10: -0.036080485 | L10: 9722.013 | M10: 1.8581236e+09
A11: BBG000F7RCJ1 | B11: aap | C11: 1.025517 | D11: -0.28447842 | E11: 21.594652 | F11: 1.0874267 | H11: 4.7969461 | I11: 18.524541 | J11: 0.44910923 | K11: -0.0025160835 | L11: 10070.213 | M11: 2.3902227e+09
A12: BBG000B9XRY4 | B12: aapl | C12: 0.99006686 | D12: 0.19382627 | E12: 28.902091 | F12: 0.014215086 | H12: 6.9581426 | I12: 23.115295 | J12: 0.19071514 | K12: 0.027210142 | L12: 24142.808 | M12: 3.5646635e+12
A13: BBG0025Y4RY4 | B13: abbv | C13: 0.21864573 | D13: 0.48411032 | E13: 26.451088 | F13: 0.019629067 | G13: 0.0063087754 | H13: 22.332725 | I13: 20.754524 | J13: 0.23427834 | K13: 0.0057858886 | L13: 18506.77 | M13: 3.0729938e+11
A14: BBG001Y2XS07 | B14: abnb | C14: 1.4001758 | D14: 0.066882992 | H14: 2.614615 | I14: 20.175483 | J14: 0.29223374
A15: BBG000KMVDV1 | B15: abr | C15: 0.94429018 | D15: 0.29737691 | E15: 21.553104 | F15: 1.3230331 | H15: 4.5758347 | I15: 17.195373 | J15: 0.37080436 | K15: 0.0052887733 | L15: 10012.199 | M15: 2.2929472e+09
A16: BBG000B9ZXB4 | B16: abt | C16: 0.17966905 | D16: 0.10875857 | E16: 26.02107 | F16: 0.19908211 | H16: 1.868429 | I16: 20.153192 | J16: 0.17700731 | K16: 0.0082342234 | L16: 17618.765 | M16: 1.9989742e+11
A17: BBG00VY1KB95 | B17: abx | C17: 0.58938634 | D17: 0.2521739 | H17: -5.0920199 | I17: 14.113635 | J17: 0.61163161
A18: BBG000BHG9K0 | B18: acad | C18: 1.1842599 | D18: -0.34515262 | E18: 21.722248 | F18: 0.15899559 | H18: 2.2625517 | I18: 16.858518 | J18: 0.54774547 | K18: -0.039433763 | L18: 10249.774 | M18: 2.7155156e+09
A19: acgl | B19: acgl | C19: 0.33468837 | D19: 0.17767943 | E19: 24.358087 | F19: 0.48431086 | H19: 4.0132948 | I19: 19.03911 | J19: 0.2264582 | K19: 0.019078993 | L19: 14452.053 | M19: 3.7895083e+10
A20: BBG000FPNN38 | B20: achc | C20: 0.72377813 | D20: -0.41512536 | E20: 22.051383 | F20: 0.71876283 | G20: 0.023987365 | H20: 2.1641743 | I20: 18.308433 | J20: 0.42811049 | K20: -0.057687845 | L20: 10722.783 | M20: 3.773932e+09
A21: BBG009KG1750 | B21: aci | C21: 0.33721761 | D21: -0.14842147 | E21: 23.117202 | F21: 0.25076346 | H21: 9.5436215 | I21: 17.893503 | J21: 0.16320851 | K21: 0.013279739 | L21: 12353.95 | M21: 1.0956541e+10
A22: acn | B22: acn | C22: 0.692461 | D22: 0.051699358 | E22: 26.142351 | F22: 0.11385011 | H22: 1.9945365 | I22: 20.547029 | J22: 0.21845999 | K22: 0.0087070868 | L22: 17866.271 | M22: 2.2567249e+11
A23: BBG000KF9J02 | B23: actg | C23: 1.0942907 | D23: 0.2417582 | E23: 19.909137 | F23: 1.2192942 | G23: 0.30811425 | H23: 1.3098867 | I23: 14.087236 | J23: 0.33933393 | K23: -0.017371473 | L23: 7891.4592 | M23: 4.4302517e+08
A24: BBG000BB5006 | B24: adbe | C24: 1.2101585 | D24: -0.21755785 | E24: 26.148711 | F24: 0.061868049 | H24: 2.1229806 | I24: 21.143599 | J24: 0.31008266 | K24: 0.0074148313 | L24: 17879.314 | M24: 2.2711238e+11
A25: BBG000BC9DK0 | B25: adc | C25: 0.091703593 | D25: 0.30933474 | E25: 22.733449 | F25: 0.69650779 | G25: -0.011924386 | H25: 1.4953877 | I25: 18.025558 | J25: 0.1795182 | K25: 0.016612088 | L25: 11748.867 | M25: 7.4646846e+09
A26: BBG00RBFBL50 | B26: adea | C26: 1.4234504 | D26: 0.36992526 | E26: 20.985395 | F26: 0.27438916 | H26: 3.1000779 | I26: 15.450983 | J26: 0.38386964 | K26: 0.014860419 | L26: 9241.6908 | M26: 1.2996942e+09
A27: BBG000BB6G37 | B27: adi | C27: 1.6893704 | D27: 0.23788141 | E27: 25.380965 | F27: 0.33745127 | H27: 1.3719756 | I27: 20.261717 | J27: 0.24298196 | K27: 0.026079072 | L27: 16350.251 | M27: 1.0539336e+11
A28: BBG000BB6WG8 | B28: adm | C28: 0.41527026 | D28: -0.23141421 | I28: 18.841909 | J28: 0.33382358
A29: BBG000JG0547 | B29: adp | C29: 0.3829761 | D29: 0.28674812 | E29: 25.516746 | F29: 0.044305531 | H29: 9.2568897 | I29: 19.915184 | J29: 0.14264031 | K29: 0.0071189046 | L29: 16614.065 | M29: 1.2072082e+11
A30: BBG000BM7HL0 | B30: adsk | C30: 1.4121299 | D30: 0.29927207 | E30: 24.86256 | F30: 0.018244541 | H30: 8.6986899 | I30: 19.822324 | J30: 0.21253953 | K30: 0.0025653896 | L30: 15368.714 | M30: 6.2758499e+10
A31: BBG000BP9WJ1 | B31: adt | C31: 1.0860454 | D31: 0.26286156 | E31: 22.429231 | F31: 0.61618553 | H31: 4.7403063 | I31: 17.611741 | J31: 0.36684824 | K31: 0.056494104 | L31: 11283.482 | M31: 5.5066986e+09
A32: BBG000B9X8C0 | B32: aee | C32: 0.059851058 | D32: 0.16218727 | E32: 23.899851 | F32: 0.49376634 | H32: 3.659089 | I32: 18.607125 | J32: 0.19606201 | K32: -0.0025036745 | L32: 13651.664 | M32: 2.3964777e+10
A33: BBG000FKMP26 | B33: aeis | C33: 2.0119865 | D33: 0.1450207 | E33: 22.186314 | F33: 0.24687225 | G33: 0.0091755296 | H33: 2.0565768 | I33: 17.019709 | J33: 0.24866348 | K33: 0.0075758764 | L33: 10920.825 | M33: 4.3191042e+09
A34: BBG000DLVDK3 | B34: aem | C34: 0.80988525 | D34: 0.63787387 | E34: 23.381917 | F34: 0.23886019 | H34: 1.5412068 | I34: 19.053526 | J34: 0.2850789 | L34: 12783.223 | M34: 1.4277021e+10
A35: BBG000BGXZB5 | B35: aeo | C35: 1.2304208 | D35: 0.054034918 | E35: 21.978967 | F35: 0.46121902 | G35: 0.069232209 | H35: 2.1975749 | I35: 18.16479 | J35: 0.33351766 | K35: 0.013836434 | L35: 10617.489 | M35: 3.5102975e+09
A36: BBG000BB9KF2 | B36: aep | C36: 0.029154253 | D36: 0.27944941 | E36: 24.647617 | F36: 0.52582538 | H36: 3.7614155 | I36: 19.40007 | J36: 0.18891292 | K36: 0.018998334 | L36: 14973.551 | M36: 5.0620227e+10
A37: BBG000C23KJ3 | B37: aes | C37: 0.75076649 | D37: -0.012900032 | E37: 22.866613 | F37: 0.38579104 | G37: -0.020357822 | H37: 15.221581 | I37: 18.964239 | J37: 0.37252989 | K37: 0.040220768 | L37: 11956.54 | M37: 8.5279325e+09
A38: BBG000BBBNC6 | B38: afl | C38: 0.28680438 | D38: 0.28844669 | E38: 24.839436 | F38: 0.35850618 | H38: 5.8422561 | I38: 19.258365 | J38: 0.19877168 | K38: 0.030640578 | L38: 15325.871 | M38: 6.1323909e+10
A39: BBG00Y7BP8Y1 | B39: afrm | C39: 2.7434539 | D39: 0.27433882 | E39: 22.145735 | F39: 0.68370721 | G39: 0.20578008 | H39: 3.5757015 | I39: 20.047543 | J39: 0.73518784 | K39: -0.041419959 | L39: 10861.012 | M39: 4.1473484e+09
A40: BBG000QY4ZD0 | B40: agio | C40: 1.4308714 | D40: 0.99865053 | E40: 21.943217 | F40: 0.30602861 | H40: 0.90409502 | I40: 17.147209 | J40: 0.50935351 | K40: -0.023920119 | L40: 10565.764 | M40: 3.3870232e+09
A41: BBG000TJ8XZ7 | B41: agnc | C41: 0.72040371 | D41: 0.20791481 | E41: 22.653669 | F41: 1.141856 | H41: 9.0973316 | I41: 18.783144 | J41: 0.18256381 | K41: -0.037288054 | L41: 11625.607 | M41: 6.8922878e+09
...

Sheet 3b-d Exposures
A1: §3b–d · Cross-sectional winsorised z-score -> loadings (live formulas)
A2: Per descriptor: med = MEDIAN; MAD = 1.4826·MEDIAN(|x−med|) (array, blanks excluded); z = clip((x−med)/MAD, ±3); loading = (z − mean)/std. (d) screen flags std ≤ 0.05.
A3: med / MAD / screen below each factor | B3: =MEDIAN('3a Raw'!C6:C1198) | D3: =MEDIAN('3a Raw'!D6:D1198) | F3: =MEDIAN('3a Raw'!E6:E1198) | H3: =MEDIAN('3a Raw'!F6:F1198) | J3: =MEDIAN('3a Raw'!G6:G1198) | L3: =MEDIAN('3a Raw'!H6:H1198) | N3: =MEDIAN('3a Raw'!I6:I1198) | P3: =MEDIAN('3a Raw'!J6:J1198) | R3: =MEDIAN('3a Raw'!K6:K1198) | T3: =MEDIAN('3a Raw'!L6:L1198) | V3: =SLOPE(U6:U1198,G6:G1198) | W3: =INTERCEPT(U6:U1198,G6:G1198) | X3: =MEDIAN(X6:X1198)
B4: {=1.4826*MEDIAN(IF('3a Raw'!C6:C1198<>"",ABS('3a Raw'!C6:C1198-B3)))} | D4: {=1.4826*MEDIAN(IF('3a Raw'!D6:D1198<>"",ABS('3a Raw'!D6:D1198-D3)))} | F4: {=1.4826*MEDIAN(IF('3a Raw'!E6:E1198<>"",ABS('3a Raw'!E6:E1198-F3)))} | H4: {=1.4826*MEDIAN(IF('3a Raw'!F6:F1198<>"",ABS('3a Raw'!F6:F1198-H3)))} | J4: {=1.4826*MEDIAN(IF('3a Raw'!G6:G1198<>"",ABS('3a Raw'!G6:G1198-J3)))} | L4: {=1.4826*MEDIAN(IF('3a Raw'!H6:H1198<>"",ABS('3a Raw'!H6:H1198-L3)))} | N4: {=1.4826*MEDIAN(IF('3a Raw'!I6:I1198<>"",ABS('3a Raw'!I6:I1198-N3)))} | P4: {=1.4826*MEDIAN(IF('3a Raw'!J6:J1198<>"",ABS('3a Raw'!J6:J1198-P3)))} | R4: {=1.4826*MEDIAN(IF('3a Raw'!K6:K1198<>"",ABS('3a Raw'!K6:K1198-R3)))} | T4: {=1.4826*MEDIAN(IF('3a Raw'!L6:L1198<>"",ABS('3a Raw'!L6:L1198-T3)))} | X4: {=1.4826*MEDIAN(IF(X6:X1198<>"",ABS(X6:X1198-X3)))}
A5: screen std (drop ≤0.05) → | B5: =STDEV(C6:C1198) | C5: Beta | D5: =STDEV(E6:E1198) | E5: Momentum | F5: =STDEV(G6:G1198) | G5: Size | H5: =STDEV(I6:I1198) | I5: Value | J5: =STDEV(K6:K1198) | K5: Growth | L5: =STDEV(M6:M1198) | M5: Leverage | N5: =STDEV(O6:O1198) | O5: Liquidity | P5: =STDEV(Q6:Q1198) | Q5: ResidVol | R5: =STDEV(S6:S1198) | S5: EarnYield | T5: =STDEV(U6:U1198) | U5: NonLinSize | V5: NonLinSize ⟂Size: slope | W5: intercept | X5: resid | Y5: z resid | Z5: NonLinSize (final) | AC5: Worked-name loading (ref, pandas) | AD5: =frame loading?
A6: BBG000C2V3D6 | B6: =IF('3a Raw'!C6="","",MAX(-3,MIN(3,('3a Raw'!C6-$B3)/$B4))) | C6: =IF(B6="","",(B6-AVERAGE(B6:B1198))/(STDEV(B6:B1198)+1E-12)) | D6: =IF('3a Raw'!D6="","",MAX(-3,MIN(3,('3a Raw'!D6-$D3)/$D4))) | E6: =IF(D6="","",(D6-AVERAGE(D6:D1198))/(STDEV(D6:D1198)+1E-12)) | F6: =IF('3a Raw'!E6="","",MAX(-3,MIN(3,('3a Raw'!E6-$F3)/$F4))) | G6: =IF(F6="","",(F6-AVERAGE(F6:F1198))/(STDEV(F6:F1198)+1E-12)) | H6: =IF('3a Raw'!F6="","",MAX(-3,MIN(3,('3a Raw'!F6-$H3)/$H4))) | I6: =IF(H6="","",(H6-AVERAGE(H6:H1198))/(STDEV(H6:H1198)+1E-12)) | J6: =IF('3a Raw'!G6="","",MAX(-3,MIN(3,('3a Raw'!G6-$J3)/$J4))) | K6: =IF(J6="","",(J6-AVERAGE(J6:J1198))/(STDEV(J6:J1198)+1E-12)) | L6: =IF('3a Raw'!H6="","",MAX(-3,MIN(3,('3a Raw'!H6-$L3)/$L4))) | M6: =IF(L6="","",(L6-AVERAGE(L6:L1198))/(STDEV(L6:L1198)+1E-12)) | N6: =IF('3a Raw'!I6="","",MAX(-3,MIN(3,('3a Raw'!I6-$N3)/$N4))) | O6: =IF(N6="","",(N6-AVERAGE(N6:N1198))/(STDEV(N6:N1198)+1E-12)) | P6: =IF('3a Raw'!J6="","",MAX(-3,MIN(3,('3a Raw'!J6-$P3)/$P4))) | Q6: =IF(P6="","",(P6-AVERAGE(P6:P1198))/(STDEV(P6:P1198)+1E-12)) | R6: =IF('3a Raw'!K6="","",MAX(-3,MIN(3,('3a Raw'!K6-$R3)/$R4))) | S6: =IF(R6="","",(R6-AVERAGE(R6:R1198))/(STDEV(R6:R1198)+1E-12)) | T6: =IF('3a Raw'!L6="","",MAX(-3,MIN(3,('3a Raw'!L6-$T3)/$T4))) | U6: =IF(T6="","",(T6-AVERAGE(T6:T1198))/(STDEV(T6:T1198)+1E-12)) | X6: =IF(U6="","",U6-($V$3*G6+$W$3)) | Y6: =IF(X6="","",MAX(-3,MIN(3,(X6-$X3)/$X4))) | Z6: =IF(Y6="","",(Y6-AVERAGE(Y6:Y1198))/(STDEV(Y6:Y1198)+1E-12)) | AB6: Beta | AC6: -0.59884271 | AD6: -0.59884271
A7: BBG00B3T3HD3 | B7: =IF('3a Raw'!C7="","",MAX(-3,MIN(3,('3a Raw'!C7-$B3)/$B4))) | C7: =IF(B7="","",(B7-AVERAGE(B6:B1198))/(STDEV(B6:B1198)+1E-12)) | D7: =IF('3a Raw'!D7="","",MAX(-3,MIN(3,('3a Raw'!D7-$D3)/$D4))) | E7: =IF(D7="","",(D7-AVERAGE(D6:D1198))/(STDEV(D6:D1198)+1E-12)) | F7: =IF('3a Raw'!E7="","",MAX(-3,MIN(3,('3a Raw'!E7-$F3)/$F4))) | G7: =IF(F7="","",(F7-AVERAGE(F6:F1198))/(STDEV(F6:F1198)+1E-12)) | H7: =IF('3a Raw'!F7="","",MAX(-3,MIN(3,('3a Raw'!F7-$H3)/$H4))) | I7: =IF(H7="","",(H7-AVERAGE(H6:H1198))/(STDEV(H6:H1198)+1E-12)) | J7: =IF('3a Raw'!G7="","",MAX(-3,MIN(3,('3a Raw'!G7-$J3)/$J4))) | K7: =IF(J7="","",(J7-AVERAGE(J6:J1198))/(STDEV(J6:J1198)+1E-12)) | L7: =IF('3a Raw'!H7="","",MAX(-3,MIN(3,('3a Raw'!H7-$L3)/$L4))) | M7: =IF(L7="","",(L7-AVERAGE(L6:L1198))/(STDEV(L6:L1198)+1E-12)) | N7: =IF('3a Raw'!I7="","",MAX(-3,MIN(3,('3a Raw'!I7-$N3)/$N4))) | O7: =IF(N7="","",(N7-AVERAGE(N6:N1198))/(STDEV(N6:N1198)+1E-12)) | P7: =IF('3a Raw'!J7="","",MAX(-3,MIN(3,('3a Raw'!J7-$P3)/$P4))) | Q7: =IF(P7="","",(P7-AVERAGE(P6:P1198))/(STDEV(P6:P1198)+1E-12)) | R7: =IF('3a Raw'!K7="","",MAX(-3,MIN(3,('3a Raw'!K7-$R3)/$R4))) | S7: =IF(R7="","",(R7-AVERAGE(R6:R1198))/(STDEV(R6:R1198)+1E-12)) | T7: =IF('3a Raw'!L7="","",MAX(-3,MIN(3,('3a Raw'!L7-$T3)/$T4))) | U7: =IF(T7="","",(T7-AVERAGE(T6:T1198))/(STDEV(T6:T1198)+1E-12)) | X7: =IF(U7="","",U7-($V$3*G7+$W$3)) | Y7: =IF(X7="","",MAX(-3,MIN(3,(X7-$X3)/$X4))) | Z7: =IF(Y7="","",(Y7-AVERAGE(Y6:Y1198))/(STDEV(Y6:Y1198)+1E-12)) | AB7: Momentum | AC7: 0.38457768 | AD7: 0.38457768
A8: BBG005P7Q881 | B8: =IF('3a Raw'!C8="","",MAX(-3,MIN(3,('3a Raw'!C8-$B3)/$B4))) | C8: =IF(B8="","",(B8-AVERAGE(B6:B1198))/(STDEV(B6:B1198)+1E-12)) | D8: =IF('3a Raw'!D8="","",MAX(-3,MIN(3,('3a Raw'!D8-$D3)/$D4))) | E8: =IF(D8="","",(D8-AVERAGE(D6:D1198))/(STDEV(D6:D1198)+1E-12)) | F8: =IF('3a Raw'!E8="","",MAX(-3,MIN(3,('3a Raw'!E8-$F3)/$F4))) | G8: =IF(F8="","",(F8-AVERAGE(F6:F1198))/(STDEV(F6:F1198)+1E-12)) | H8: =IF('3a Raw'!F8="","",MAX(-3,MIN(3,('3a Raw'!F8-$H3)/$H4))) | I8: =IF(H8="","",(H8-AVERAGE(H6:H1198))/(STDEV(H6:H1198)+1E-12)) | J8: =IF('3a Raw'!G8="","",MAX(-3,MIN(3,('3a Raw'!G8-$J3)/$J4))) | K8: =IF(J8="","",(J8-AVERAGE(J6:J1198))/(STDEV(J6:J1198)+1E-12)) | L8: =IF('3a Raw'!H8="","",MAX(-3,MIN(3,('3a Raw'!H8-$L3)/$L4))) | M8: =IF(L8="","",(L8-AVERAGE(L6:L1198))/(STDEV(L6:L1198)+1E-12)) | N8: =IF('3a Raw'!I8="","",MAX(-3,MIN(3,('3a Raw'!I8-$N3)/$N4))) | O8: =IF(N8="","",(N8-AVERAGE(N6:N1198))/(STDEV(N6:N1198)+1E-12)) | P8: =IF('3a Raw'!J8="","",MAX(-3,MIN(3,('3a Raw'!J8-$P3)/$P4))) | Q8: =IF(P8="","",(P8-AVERAGE(P6:P1198))/(STDEV(P6:P1198)+1E-12)) | R8: =IF('3a Raw'!K8="","",MAX(-3,MIN(3,('3a Raw'!K8-$R3)/$R4))) | S8: =IF(R8="","",(R8-AVERAGE(R6:R1198))/(STDEV(R6:R1198)+1E-12)) | T8: =IF('3a Raw'!L8="","",MAX(-3,MIN(3,('3a Raw'!L8-$T3)/$T4))) | U8: =IF(T8="","",(T8-AVERAGE(T6:T1198))/(STDEV(T6:T1198)+1E-12)) | X8: =IF(U8="","",U8-($V$3*G8+$W$3)) | Y8: =IF(X8="","",MAX(-3,MIN(3,(X8-$X3)/$X4))) | Z8: =IF(Y8="","",(Y8-AVERAGE(Y6:Y1198))/(STDEV(Y6:Y1198)+1E-12)) | AB8: Size | AC8: 2.8070623 | AD8: 2.8070623
A9: BBG00P2HLNY3 | B9: =IF('3a Raw'!C9="","",MAX(-3,MIN(3,('3a Raw'!C9-$B3)/$B4))) | C9: =IF(B9="","",(B9-AVERAGE(B6:B1198))/(STDEV(B6:B1198)+1E-12)) | D9: =IF('3a Raw'!D9="","",MAX(-3,MIN(3,('3a Raw'!D9-$D3)/$D4))) | E9: =IF(D9="","",(D9-AVERAGE(D6:D1198))/(STDEV(D6:D1198)+1E-12)) | F9: =IF('3a Raw'!E9="","",MAX(-3,MIN(3,('3a Raw'!E9-$F3)/$F4))) | G9: =IF(F9="","",(F9-AVERAGE(F6:F1198))/(STDEV(F6:F1198)+1E-12)) | H9: =IF('3a Raw'!F9="","",MAX(-3,MIN(3,('3a Raw'!F9-$H3)/$H4))) | I9: =IF(H9="","",(H9-AVERAGE(H6:H1198))/(STDEV(H6:H1198)+1E-12)) | J9: =IF('3a Raw'!G9="","",MAX(-3,MIN(3,('3a Raw'!G9-$J3)/$J4))) | K9: =IF(J9="","",(J9-AVERAGE(J6:J1198))/(STDEV(J6:J1198)+1E-12)) | L9: =IF('3a Raw'!H9="","",MAX(-3,MIN(3,('3a Raw'!H9-$L3)/$L4))) | M9: =IF(L9="","",(L9-AVERAGE(L6:L1198))/(STDEV(L6:L1198)+1E-12)) | N9: =IF('3a Raw'!I9="","",MAX(-3,MIN(3,('3a Raw'!I9-$N3)/$N4))) | O9: =IF(N9="","",(N9-AVERAGE(N6:N1198))/(STDEV(N6:N1198)+1E-12)) | P9: =IF('3a Raw'!J9="","",MAX(-3,MIN(3,('3a Raw'!J9-$P3)/$P4))) | Q9: =IF(P9="","",(P9-AVERAGE(P6:P1198))/(STDEV(P6:P1198)+1E-12)) | R9: =IF('3a Raw'!K9="","",MAX(-3,MIN(3,('3a Raw'!K9-$R3)/$R4))) | S9: =IF(R9="","",(R9-AVERAGE(R6:R1198))/(STDEV(R6:R1198)+1E-12)) | T9: =IF('3a Raw'!L9="","",MAX(-3,MIN(3,('3a Raw'!L9-$T3)/$T4))) | U9: =IF(T9="","",(T9-AVERAGE(T6:T1198))/(STDEV(T6:T1198)+1E-12)) | X9: =IF(U9="","",U9-($V$3*G9+$W$3)) | Y9: =IF(X9="","",MAX(-3,MIN(3,(X9-$X3)/$X4))) | Z9: =IF(Y9="","",(Y9-AVERAGE(Y6:Y1198))/(STDEV(Y6:Y1198)+1E-12)) | AB9: Value | AC9: 0.54777451 | AD9: 0.54777451
A10: BBG000D6VW15 | B10: =IF('3a Raw'!C10="","",MAX(-3,MIN(3,('3a Raw'!C10-$B3)/$B4))) | C10: =IF(B10="","",(B10-AVERAGE(B6:B1198))/(STDEV(B6:B1198)+1E-12)) | D10: =IF('3a Raw'!D10="","",MAX(-3,MIN(3,('3a Raw'!D10-$D3)/$D4))) | E10: =IF(D10="","",(D10-AVERAGE(D6:D1198))/(STDEV(D6:D1198)+1E-12)) | F10: =IF('3a Raw'!E10="","",MAX(-3,MIN(3,('3a Raw'!E10-$F3)/$F4))) | G10: =IF(F10="","",(F10-AVERAGE(F6:F1198))/(STDEV(F6:F1198)+1E-12)) | H10: =IF('3a Raw'!F10="","",MAX(-3,MIN(3,('3a Raw'!F10-$H3)/$H4))) | I10: =IF(H10="","",(H10-AVERAGE(H6:H1198))/(STDEV(H6:H1198)+1E-12)) | J10: =IF('3a Raw'!G10="","",MAX(-3,MIN(3,('3a Raw'!G10-$J3)/$J4))) | K10: =IF(J10="","",(J10-AVERAGE(J6:J1198))/(STDEV(J6:J1198)+1E-12)) | L10: =IF('3a Raw'!H10="","",MAX(-3,MIN(3,('3a Raw'!H10-$L3)/$L4))) | M10: =IF(L10="","",(L10-AVERAGE(L6:L1198))/(STDEV(L6:L1198)+1E-12)) | N10: =IF('3a Raw'!I10="","",MAX(-3,MIN(3,('3a Raw'!I10-$N3)/$N4))) | O10: =IF(N10="","",(N10-AVERAGE(N6:N1198))/(STDEV(N6:N1198)+1E-12)) | P10: =IF('3a Raw'!J10="","",MAX(-3,MIN(3,('3a Raw'!J10-$P3)/$P4))) | Q10: =IF(P10="","",(P10-AVERAGE(P6:P1198))/(STDEV(P6:P1198)+1E-12)) | R10: =IF('3a Raw'!K10="","",MAX(-3,MIN(3,('3a Raw'!K10-$R3)/$R4))) | S10: =IF(R10="","",(R10-AVERAGE(R6:R1198))/(STDEV(R6:R1198)+1E-12)) | T10: =IF('3a Raw'!L10="","",MAX(-3,MIN(3,('3a Raw'!L10-$T3)/$T4))) | U10: =IF(T10="","",(T10-AVERAGE(T6:T1198))/(STDEV(T6:T1198)+1E-12)) | X10: =IF(U10="","",U10-($V$3*G10+$W$3)) | Y10: =IF(X10="","",MAX(-3,MIN(3,(X10-$X3)/$X4))) | Z10: =IF(Y10="","",(Y10-AVERAGE(Y6:Y1198))/(STDEV(Y6:Y1198)+1E-12)) | AB10: Growth
A11: BBG000F7RCJ1 | B11: =IF('3a Raw'!C11="","",MAX(-3,MIN(3,('3a Raw'!C11-$B3)/$B4))) | C11: =IF(B11="","",(B11-AVERAGE(B6:B1198))/(STDEV(B6:B1198)+1E-12)) | D11: =IF('3a Raw'!D11="","",MAX(-3,MIN(3,('3a Raw'!D11-$D3)/$D4))) | E11: =IF(D11="","",(D11-AVERAGE(D6:D1198))/(STDEV(D6:D1198)+1E-12)) | F11: =IF('3a Raw'!E11="","",MAX(-3,MIN(3,('3a Raw'!E11-$F3)/$F4))) | G11: =IF(F11="","",(F11-AVERAGE(F6:F1198))/(STDEV(F6:F1198)+1E-12)) | H11: =IF('3a Raw'!F11="","",MAX(-3,MIN(3,('3a Raw'!F11-$H3)/$H4))) | I11: =IF(H11="","",(H11-AVERAGE(H6:H1198))/(STDEV(H6:H1198)+1E-12)) | J11: =IF('3a Raw'!G11="","",MAX(-3,MIN(3,('3a Raw'!G11-$J3)/$J4))) | K11: =IF(J11="","",(J11-AVERAGE(J6:J1198))/(STDEV(J6:J1198)+1E-12)) | L11: =IF('3a Raw'!H11="","",MAX(-3,MIN(3,('3a Raw'!H11-$L3)/$L4))) | M11: =IF(L11="","",(L11-AVERAGE(L6:L1198))/(STDEV(L6:L1198)+1E-12)) | N11: =IF('3a Raw'!I11="","",MAX(-3,MIN(3,('3a Raw'!I11-$N3)/$N4))) | O11: =IF(N11="","",(N11-AVERAGE(N6:N1198))/(STDEV(N6:N1198)+1E-12)) | P11: =IF('3a Raw'!J11="","",MAX(-3,MIN(3,('3a Raw'!J11-$P3)/$P4))) | Q11: =IF(P11="","",(P11-AVERAGE(P6:P1198))/(STDEV(P6:P1198)+1E-12)) | R11: =IF('3a Raw'!K11="","",MAX(-3,MIN(3,('3a Raw'!K11-$R3)/$R4))) | S11: =IF(R11="","",(R11-AVERAGE(R6:R1198))/(STDEV(R6:R1198)+1E-12)) | T11: =IF('3a Raw'!L11="","",MAX(-3,MIN(3,('3a Raw'!L11-$T3)/$T4))) | U11: =IF(T11="","",(T11-AVERAGE(T6:T1198))/(STDEV(T6:T1198)+1E-12)) | X11: =IF(U11="","",U11-($V$3*G11+$W$3)) | Y11: =IF(X11="","",MAX(-3,MIN(3,(X11-$X3)/$X4))) | Z11: =IF(Y11="","",(Y11-AVERAGE(Y6:Y1198))/(STDEV(Y6:Y1198)+1E-12)) | AB11: Leverage | AC11: -0.55031501 | AD11: -0.55031501
A12: BBG000B9XRY4 | B12: =IF('3a Raw'!C12="","",MAX(-3,MIN(3,('3a Raw'!C12-$B3)/$B4))) | C12: =IF(B12="","",(B12-AVERAGE(B6:B1198))/(STDEV(B6:B1198)+1E-12)) | D12: =IF('3a Raw'!D12="","",MAX(-3,MIN(3,('3a Raw'!D12-$D3)/$D4))) | E12: =IF(D12="","",(D12-AVERAGE(D6:D1198))/(STDEV(D6:D1198)+1E-12)) | F12: =IF('3a Raw'!E12="","",MAX(-3,MIN(3,('3a Raw'!E12-$F3)/$F4))) | G12: =IF(F12="","",(F12-AVERAGE(F6:F1198))/(STDEV(F6:F1198)+1E-12)) | H12: =IF('3a Raw'!F12="","",MAX(-3,MIN(3,('3a Raw'!F12-$H3)/$H4))) | I12: =IF(H12="","",(H12-AVERAGE(H6:H1198))/(STDEV(H6:H1198)+1E-12)) | J12: =IF('3a Raw'!G12="","",MAX(-3,MIN(3,('3a Raw'!G12-$J3)/$J4))) | K12: =IF(J12="","",(J12-AVERAGE(J6:J1198))/(STDEV(J6:J1198)+1E-12)) | L12: =IF('3a Raw'!H12="","",MAX(-3,MIN(3,('3a Raw'!H12-$L3)/$L4))) | M12: =IF(L12="","",(L12-AVERAGE(L6:L1198))/(STDEV(L6:L1198)+1E-12)) | N12: =IF('3a Raw'!I12="","",MAX(-3,MIN(3,('3a Raw'!I12-$N3)/$N4))) | O12: =IF(N12="","",(N12-AVERAGE(N6:N1198))/(STDEV(N6:N1198)+1E-12)) | P12: =IF('3a Raw'!J12="","",MAX(-3,MIN(3,('3a Raw'!J12-$P3)/$P4))) | Q12: =IF(P12="","",(P12-AVERAGE(P6:P1198))/(STDEV(P6:P1198)+1E-12)) | R12: =IF('3a Raw'!K12="","",MAX(-3,MIN(3,('3a Raw'!K12-$R3)/$R4))) | S12: =IF(R12="","",(R12-AVERAGE(R6:R1198))/(STDEV(R6:R1198)+1E-12)) | T12: =IF('3a Raw'!L12="","",MAX(-3,MIN(3,('3a Raw'!L12-$T3)/$T4))) | U12: =IF(T12="","",(T12-AVERAGE(T6:T1198))/(STDEV(T6:T1198)+1E-12)) | X12: =IF(U12="","",U12-($V$3*G12+$W$3)) | Y12: =IF(X12="","",MAX(-3,MIN(3,(X12-$X3)/$X4))) | Z12: =IF(Y12="","",(Y12-AVERAGE(Y6:Y1198))/(STDEV(Y6:Y1198)+1E-12)) | AB12: Liquidity | AC12: 1.8869457 | AD12: 1.8869457
A13: BBG0025Y4RY4 | B13: =IF('3a Raw'!C13="","",MAX(-3,MIN(3,('3a Raw'!C13-$B3)/$B4))) | C13: =IF(B13="","",(B13-AVERAGE(B6:B1198))/(STDEV(B6:B1198)+1E-12)) | D13: =IF('3a Raw'!D13="","",MAX(-3,MIN(3,('3a Raw'!D13-$D3)/$D4))) | E13: =IF(D13="","",(D13-AVERAGE(D6:D1198))/(STDEV(D6:D1198)+1E-12)) | F13: =IF('3a Raw'!E13="","",MAX(-3,MIN(3,('3a Raw'!E13-$F3)/$F4))) | G13: =IF(F13="","",(F13-AVERAGE(F6:F1198))/(STDEV(F6:F1198)+1E-12)) | H13: =IF('3a Raw'!F13="","",MAX(-3,MIN(3,('3a Raw'!F13-$H3)/$H4))) | I13: =IF(H13="","",(H13-AVERAGE(H6:H1198))/(STDEV(H6:H1198)+1E-12)) | J13: =IF('3a Raw'!G13="","",MAX(-3,MIN(3,('3a Raw'!G13-$J3)/$J4))) | K13: =IF(J13="","",(J13-AVERAGE(J6:J1198))/(STDEV(J6:J1198)+1E-12)) | L13: =IF('3a Raw'!H13="","",MAX(-3,MIN(3,('3a Raw'!H13-$L3)/$L4))) | M13: =IF(L13="","",(L13-AVERAGE(L6:L1198))/(STDEV(L6:L1198)+1E-12)) | N13: =IF('3a Raw'!I13="","",MAX(-3,MIN(3,('3a Raw'!I13-$N3)/$N4))) | O13: =IF(N13="","",(N13-AVERAGE(N6:N1198))/(STDEV(N6:N1198)+1E-12)) | P13: =IF('3a Raw'!J13="","",MAX(-3,MIN(3,('3a Raw'!J13-$P3)/$P4))) | Q13: =IF(P13="","",(P13-AVERAGE(P6:P1198))/(STDEV(P6:P1198)+1E-12)) | R13: =IF('3a Raw'!K13="","",MAX(-3,MIN(3,('3a Raw'!K13-$R3)/$R4))) | S13: =IF(R13="","",(R13-AVERAGE(R6:R1198))/(STDEV(R6:R1198)+1E-12)) | T13: =IF('3a Raw'!L13="","",MAX(-3,MIN(3,('3a Raw'!L13-$T3)/$T4))) | U13: =IF(T13="","",(T13-AVERAGE(T6:T1198))/(STDEV(T6:T1198)+1E-12)) | X13: =IF(U13="","",U13-($V$3*G13+$W$3)) | Y13: =IF(X13="","",MAX(-3,MIN(3,(X13-$X3)/$X4))) | Z13: =IF(Y13="","",(Y13-AVERAGE(Y6:Y1198))/(STDEV(Y6:Y1198)+1E-12)) | AB13: ResidVol | AC13: 0.2243422 | AD13: 0.2243422
A14: BBG001Y2XS07 | B14: =IF('3a Raw'!C14="","",MAX(-3,MIN(3,('3a Raw'!C14-$B3)/$B4))) | C14: =IF(B14="","",(B14-AVERAGE(B6:B1198))/(STDEV(B6:B1198)+1E-12)) | D14: =IF('3a Raw'!D14="","",MAX(-3,MIN(3,('3a Raw'!D14-$D3)/$D4))) | E14: =IF(D14="","",(D14-AVERAGE(D6:D1198))/(STDEV(D6:D1198)+1E-12)) | F14: =IF('3a Raw'!E14="","",MAX(-3,MIN(3,('3a Raw'!E14-$F3)/$F4))) | G14: =IF(F14="","",(F14-AVERAGE(F6:F1198))/(STDEV(F6:F1198)+1E-12)) | H14: =IF('3a Raw'!F14="","",MAX(-3,MIN(3,('3a Raw'!F14-$H3)/$H4))) | I14: =IF(H14="","",(H14-AVERAGE(H6:H1198))/(STDEV(H6:H1198)+1E-12)) | J14: =IF('3a Raw'!G14="","",MAX(-3,MIN(3,('3a Raw'!G14-$J3)/$J4))) | K14: =IF(J14="","",(J14-AVERAGE(J6:J1198))/(STDEV(J6:J1198)+1E-12)) | L14: =IF('3a Raw'!H14="","",MAX(-3,MIN(3,('3a Raw'!H14-$L3)/$L4))) | M14: =IF(L14="","",(L14-AVERAGE(L6:L1198))/(STDEV(L6:L1198)+1E-12)) | N14: =IF('3a Raw'!I14="","",MAX(-3,MIN(3,('3a Raw'!I14-$N3)/$N4))) | O14: =IF(N14="","",(N14-AVERAGE(N6:N1198))/(STDEV(N6:N1198)+1E-12)) | P14: =IF('3a Raw'!J14="","",MAX(-3,MIN(3,('3a Raw'!J14-$P3)/$P4))) | Q14: =IF(P14="","",(P14-AVERAGE(P6:P1198))/(STDEV(P6:P1198)+1E-12)) | R14: =IF('3a Raw'!K14="","",MAX(-3,MIN(3,('3a Raw'!K14-$R3)/$R4))) | S14: =IF(R14="","",(R14-AVERAGE(R6:R1198))/(STDEV(R6:R1198)+1E-12)) | T14: =IF('3a Raw'!L14="","",MAX(-3,MIN(3,('3a Raw'!L14-$T3)/$T4))) | U14: =IF(T14="","",(T14-AVERAGE(T6:T1198))/(STDEV(T6:T1198)+1E-12)) | X14: =IF(U14="","",U14-($V$3*G14+$W$3)) | Y14: =IF(X14="","",MAX(-3,MIN(3,(X14-$X3)/$X4))) | Z14: =IF(Y14="","",(Y14-AVERAGE(Y6:Y1198))/(STDEV(Y6:Y1198)+1E-12)) | AB14: EarnYield | AC14: 1.096686 | AD14: 1.096686
A15: BBG000KMVDV1 | B15: =IF('3a Raw'!C15="","",MAX(-3,MIN(3,('3a Raw'!C15-$B3)/$B4))) | C15: =IF(B15="","",(B15-AVERAGE(B6:B1198))/(STDEV(B6:B1198)+1E-12)) | D15: =IF('3a Raw'!D15="","",MAX(-3,MIN(3,('3a Raw'!D15-$D3)/$D4))) | E15: =IF(D15="","",(D15-AVERAGE(D6:D1198))/(STDEV(D6:D1198)+1E-12)) | F15: =IF('3a Raw'!E15="","",MAX(-3,MIN(3,('3a Raw'!E15-$F3)/$F4))) | G15: =IF(F15="","",(F15-AVERAGE(F6:F1198))/(STDEV(F6:F1198)+1E-12)) | H15: =IF('3a Raw'!F15="","",MAX(-3,MIN(3,('3a Raw'!F15-$H3)/$H4))) | I15: =IF(H15="","",(H15-AVERAGE(H6:H1198))/(STDEV(H6:H1198)+1E-12)) | J15: =IF('3a Raw'!G15="","",MAX(-3,MIN(3,('3a Raw'!G15-$J3)/$J4))) | K15: =IF(J15="","",(J15-AVERAGE(J6:J1198))/(STDEV(J6:J1198)+1E-12)) | L15: =IF('3a Raw'!H15="","",MAX(-3,MIN(3,('3a Raw'!H15-$L3)/$L4))) | M15: =IF(L15="","",(L15-AVERAGE(L6:L1198))/(STDEV(L6:L1198)+1E-12)) | N15: =IF('3a Raw'!I15="","",MAX(-3,MIN(3,('3a Raw'!I15-$N3)/$N4))) | O15: =IF(N15="","",(N15-AVERAGE(N6:N1198))/(STDEV(N6:N1198)+1E-12)) | P15: =IF('3a Raw'!J15="","",MAX(-3,MIN(3,('3a Raw'!J15-$P3)/$P4))) | Q15: =IF(P15="","",(P15-AVERAGE(P6:P1198))/(STDEV(P6:P1198)+1E-12)) | R15: =IF('3a Raw'!K15="","",MAX(-3,MIN(3,('3a Raw'!K15-$R3)/$R4))) | S15: =IF(R15="","",(R15-AVERAGE(R6:R1198))/(STDEV(R6:R1198)+1E-12)) | T15: =IF('3a Raw'!L15="","",MAX(-3,MIN(3,('3a Raw'!L15-$T3)/$T4))) | U15: =IF(T15="","",(T15-AVERAGE(T6:T1198))/(STDEV(T6:T1198)+1E-12)) | X15: =IF(U15="","",U15-($V$3*G15+$W$3)) | Y15: =IF(X15="","",MAX(-3,MIN(3,(X15-$X3)/$X4))) | Z15: =IF(Y15="","",(Y15-AVERAGE(Y6:Y1198))/(STDEV(Y6:Y1198)+1E-12)) | AB15: NonLinSize | AC15: 1.9467768 | AD15: 1.9467768
A16: BBG000B9ZXB4 | B16: =IF('3a Raw'!C16="","",MAX(-3,MIN(3,('3a Raw'!C16-$B3)/$B4))) | C16: =IF(B16="","",(B16-AVERAGE(B6:B1198))/(STDEV(B6:B1198)+1E-12)) | D16: =IF('3a Raw'!D16="","",MAX(-3,MIN(3,('3a Raw'!D16-$D3)/$D4))) | E16: =IF(D16="","",(D16-AVERAGE(D6:D1198))/(STDEV(D6:D1198)+1E-12)) | F16: =IF('3a Raw'!E16="","",MAX(-3,MIN(3,('3a Raw'!E16-$F3)/$F4))) | G16: =IF(F16="","",(F16-AVERAGE(F6:F1198))/(STDEV(F6:F1198)+1E-12)) | H16: =IF('3a Raw'!F16="","",MAX(-3,MIN(3,('3a Raw'!F16-$H3)/$H4))) | I16: =IF(H16="","",(H16-AVERAGE(H6:H1198))/(STDEV(H6:H1198)+1E-12)) | J16: =IF('3a Raw'!G16="","",MAX(-3,MIN(3,('3a Raw'!G16-$J3)/$J4))) | K16: =IF(J16="","",(J16-AVERAGE(J6:J1198))/(STDEV(J6:J1198)+1E-12)) | L16: =IF('3a Raw'!H16="","",MAX(-3,MIN(3,('3a Raw'!H16-$L3)/$L4))) | M16: =IF(L16="","",(L16-AVERAGE(L6:L1198))/(STDEV(L6:L1198)+1E-12)) | N16: =IF('3a Raw'!I16="","",MAX(-3,MIN(3,('3a Raw'!I16-$N3)/$N4))) | O16: =IF(N16="","",(N16-AVERAGE(N6:N1198))/(STDEV(N6:N1198)+1E-12)) | P16: =IF('3a Raw'!J16="","",MAX(-3,MIN(3,('3a Raw'!J16-$P3)/$P4))) | Q16: =IF(P16="","",(P16-AVERAGE(P6:P1198))/(STDEV(P6:P1198)+1E-12)) | R16: =IF('3a Raw'!K16="","",MAX(-3,MIN(3,('3a Raw'!K16-$R3)/$R4))) | S16: =IF(R16="","",(R16-AVERAGE(R6:R1198))/(STDEV(R6:R1198)+1E-12)) | T16: =IF('3a Raw'!L16="","",MAX(-3,MIN(3,('3a Raw'!L16-$T3)/$T4))) | U16: =IF(T16="","",(T16-AVERAGE(T6:T1198))/(STDEV(T6:T1198)+1E-12)) | X16: =IF(U16="","",U16-($V$3*G16+$W$3)) | Y16: =IF(X16="","",MAX(-3,MIN(3,(X16-$X3)/$X4))) | Z16: =IF(Y16="","",(Y16-AVERAGE(Y6:Y1198))/(STDEV(Y6:Y1198)+1E-12))
A17: BBG00VY1KB95 | B17: =IF('3a Raw'!C17="","",MAX(-3,MIN(3,('3a Raw'!C17-$B3)/$B4))) | C17: =IF(B17="","",(B17-AVERAGE(B6:B1198))/(STDEV(B6:B1198)+1E-12)) | D17: =IF('3a Raw'!D17="","",MAX(-3,MIN(3,('3a Raw'!D17-$D3)/$D4))) | E17: =IF(D17="","",(D17-AVERAGE(D6:D1198))/(STDEV(D6:D1198)+1E-12)) | F17: =IF('3a Raw'!E17="","",MAX(-3,MIN(3,('3a Raw'!E17-$F3)/$F4))) | G17: =IF(F17="","",(F17-AVERAGE(F6:F1198))/(STDEV(F6:F1198)+1E-12)) | H17: =IF('3a Raw'!F17="","",MAX(-3,MIN(3,('3a Raw'!F17-$H3)/$H4))) | I17: =IF(H17="","",(H17-AVERAGE(H6:H1198))/(STDEV(H6:H1198)+1E-12)) | J17: =IF('3a Raw'!G17="","",MAX(-3,MIN(3,('3a Raw'!G17-$J3)/$J4))) | K17: =IF(J17="","",(J17-AVERAGE(J6:J1198))/(STDEV(J6:J1198)+1E-12)) | L17: =IF('3a Raw'!H17="","",MAX(-3,MIN(3,('3a Raw'!H17-$L3)/$L4))) | M17: =IF(L17="","",(L17-AVERAGE(L6:L1198))/(STDEV(L6:L1198)+1E-12)) | N17: =IF('3a Raw'!I17="","",MAX(-3,MIN(3,('3a Raw'!I17-$N3)/$N4))) | O17: =IF(N17="","",(N17-AVERAGE(N6:N1198))/(STDEV(N6:N1198)+1E-12)) | P17: =IF('3a Raw'!J17="","",MAX(-3,MIN(3,('3a Raw'!J17-$P3)/$P4))) | Q17: =IF(P17="","",(P17-AVERAGE(P6:P1198))/(STDEV(P6:P1198)+1E-12)) | R17: =IF('3a Raw'!K17="","",MAX(-3,MIN(3,('3a Raw'!K17-$R3)/$R4))) | S17: =IF(R17="","",(R17-AVERAGE(R6:R1198))/(STDEV(R6:R1198)+1E-12)) | T17: =IF('3a Raw'!L17="","",MAX(-3,MIN(3,('3a Raw'!L17-$T3)/$T4))) | U17: =IF(T17="","",(T17-AVERAGE(T6:T1198))/(STDEV(T6:T1198)+1E-12)) | X17: =IF(U17="","",U17-($V$3*G17+$W$3)) | Y17: =IF(X17="","",MAX(-3,MIN(3,(X17-$X3)/$X4))) | Z17: =IF(Y17="","",(Y17-AVERAGE(Y6:Y1198))/(STDEV(Y6:Y1198)+1E-12))
A18: BBG000BHG9K0 | B18: =IF('3a Raw'!C18="","",MAX(-3,MIN(3,('3a Raw'!C18-$B3)/$B4))) | C18: =IF(B18="","",(B18-AVERAGE(B6:B1198))/(STDEV(B6:B1198)+1E-12)) | D18: =IF('3a Raw'!D18="","",MAX(-3,MIN(3,('3a Raw'!D18-$D3)/$D4))) | E18: =IF(D18="","",(D18-AVERAGE(D6:D1198))/(STDEV(D6:D1198)+1E-12)) | F18: =IF('3a Raw'!E18="","",MAX(-3,MIN(3,('3a Raw'!E18-$F3)/$F4))) | G18: =IF(F18="","",(F18-AVERAGE(F6:F1198))/(STDEV(F6:F1198)+1E-12)) | H18: =IF('3a Raw'!F18="","",MAX(-3,MIN(3,('3a Raw'!F18-$H3)/$H4))) | I18: =IF(H18="","",(H18-AVERAGE(H6:H1198))/(STDEV(H6:H1198)+1E-12)) | J18: =IF('3a Raw'!G18="","",MAX(-3,MIN(3,('3a Raw'!G18-$J3)/$J4))) | K18: =IF(J18="","",(J18-AVERAGE(J6:J1198))/(STDEV(J6:J1198)+1E-12)) | L18: =IF('3a Raw'!H18="","",MAX(-3,MIN(3,('3a Raw'!H18-$L3)/$L4))) | M18: =IF(L18="","",(L18-AVERAGE(L6:L1198))/(STDEV(L6:L1198)+1E-12)) | N18: =IF('3a Raw'!I18="","",MAX(-3,MIN(3,('3a Raw'!I18-$N3)/$N4))) | O18: =IF(N18="","",(N18-AVERAGE(N6:N1198))/(STDEV(N6:N1198)+1E-12)) | P18: =IF('3a Raw'!J18="","",MAX(-3,MIN(3,('3a Raw'!J18-$P3)/$P4))) | Q18: =IF(P18="","",(P18-AVERAGE(P6:P1198))/(STDEV(P6:P1198)+1E-12)) | R18: =IF('3a Raw'!K18="","",MAX(-3,MIN(3,('3a Raw'!K18-$R3)/$R4))) | S18: =IF(R18="","",(R18-AVERAGE(R6:R1198))/(STDEV(R6:R1198)+1E-12)) | T18: =IF('3a Raw'!L18="","",MAX(-3,MIN(3,('3a Raw'!L18-$T3)/$T4))) | U18: =IF(T18="","",(T18-AVERAGE(T6:T1198))/(STDEV(T6:T1198)+1E-12)) | X18: =IF(U18="","",U18-($V$3*G18+$W$3)) | Y18: =IF(X18="","",MAX(-3,MIN(3,(X18-$X3)/$X4))) | Z18: =IF(Y18="","",(Y18-AVERAGE(Y6:Y1198))/(STDEV(Y6:Y1198)+1E-12))
A19: acgl | B19: =IF('3a Raw'!C19="","",MAX(-3,MIN(3,('3a Raw'!C19-$B3)/$B4))) | C19: =IF(B19="","",(B19-AVERAGE(B6:B1198))/(STDEV(B6:B1198)+1E-12)) | D19: =IF('3a Raw'!D19="","",MAX(-3,MIN(3,('3a Raw'!D19-$D3)/$D4))) | E19: =IF(D19="","",(D19-AVERAGE(D6:D1198))/(STDEV(D6:D1198)+1E-12)) | F19: =IF('3a Raw'!E19="","",MAX(-3,MIN(3,('3a Raw'!E19-$F3)/$F4))) | G19: =IF(F19="","",(F19-AVERAGE(F6:F1198))/(STDEV(F6:F1198)+1E-12)) | H19: =IF('3a Raw'!F19="","",MAX(-3,MIN(3,('3a Raw'!F19-$H3)/$H4))) | I19: =IF(H19="","",(H19-AVERAGE(H6:H1198))/(STDEV(H6:H1198)+1E-12)) | J19: =IF('3a Raw'!G19="","",MAX(-3,MIN(3,('3a Raw'!G19-$J3)/$J4))) | K19: =IF(J19="","",(J19-AVERAGE(J6:J1198))/(STDEV(J6:J1198)+1E-12)) | L19: =IF('3a Raw'!H19="","",MAX(-3,MIN(3,('3a Raw'!H19-$L3)/$L4))) | M19: =IF(L19="","",(L19-AVERAGE(L6:L1198))/(STDEV(L6:L1198)+1E-12)) | N19: =IF('3a Raw'!I19="","",MAX(-3,MIN(3,('3a Raw'!I19-$N3)/$N4))) | O19: =IF(N19="","",(N19-AVERAGE(N6:N1198))/(STDEV(N6:N1198)+1E-12)) | P19: =IF('3a Raw'!J19="","",MAX(-3,MIN(3,('3a Raw'!J19-$P3)/$P4))) | Q19: =IF(P19="","",(P19-AVERAGE(P6:P1198))/(STDEV(P6:P1198)+1E-12)) | R19: =IF('3a Raw'!K19="","",MAX(-3,MIN(3,('3a Raw'!K19-$R3)/$R4))) | S19: =IF(R19="","",(R19-AVERAGE(R6:R1198))/(STDEV(R6:R1198)+1E-12)) | T19: =IF('3a Raw'!L19="","",MAX(-3,MIN(3,('3a Raw'!L19-$T3)/$T4))) | U19: =IF(T19="","",(T19-AVERAGE(T6:T1198))/(STDEV(T6:T1198)+1E-12)) | X19: =IF(U19="","",U19-($V$3*G19+$W$3)) | Y19: =IF(X19="","",MAX(-3,MIN(3,(X19-$X3)/$X4))) | Z19: =IF(Y19="","",(Y19-AVERAGE(Y6:Y1198))/(STDEV(Y6:Y1198)+1E-12))
A20: BBG000FPNN38 | B20: =IF('3a Raw'!C20="","",MAX(-3,MIN(3,('3a Raw'!C20-$B3)/$B4))) | C20: =IF(B20="","",(B20-AVERAGE(B6:B1198))/(STDEV(B6:B1198)+1E-12)) | D20: =IF('3a Raw'!D20="","",MAX(-3,MIN(3,('3a Raw'!D20-$D3)/$D4))) | E20: =IF(D20="","",(D20-AVERAGE(D6:D1198))/(STDEV(D6:D1198)+1E-12)) | F20: =IF('3a Raw'!E20="","",MAX(-3,MIN(3,('3a Raw'!E20-$F3)/$F4))) | G20: =IF(F20="","",(F20-AVERAGE(F6:F1198))/(STDEV(F6:F1198)+1E-12)) | H20: =IF('3a Raw'!F20="","",MAX(-3,MIN(3,('3a Raw'!F20-$H3)/$H4))) | I20: =IF(H20="","",(H20-AVERAGE(H6:H1198))/(STDEV(H6:H1198)+1E-12)) | J20: =IF('3a Raw'!G20="","",MAX(-3,MIN(3,('3a Raw'!G20-$J3)/$J4))) | K20: =IF(J20="","",(J20-AVERAGE(J6:J1198))/(STDEV(J6:J1198)+1E-12)) | L20: =IF('3a Raw'!H20="","",MAX(-3,MIN(3,('3a Raw'!H20-$L3)/$L4))) | M20: =IF(L20="","",(L20-AVERAGE(L6:L1198))/(STDEV(L6:L1198)+1E-12)) | N20: =IF('3a Raw'!I20="","",MAX(-3,MIN(3,('3a Raw'!I20-$N3)/$N4))) | O20: =IF(N20="","",(N20-AVERAGE(N6:N1198))/(STDEV(N6:N1198)+1E-12)) | P20: =IF('3a Raw'!J20="","",MAX(-3,MIN(3,('3a Raw'!J20-$P3)/$P4))) | Q20: =IF(P20="","",(P20-AVERAGE(P6:P1198))/(STDEV(P6:P1198)+1E-12)) | R20: =IF('3a Raw'!K20="","",MAX(-3,MIN(3,('3a Raw'!K20-$R3)/$R4))) | S20: =IF(R20="","",(R20-AVERAGE(R6:R1198))/(STDEV(R6:R1198)+1E-12)) | T20: =IF('3a Raw'!L20="","",MAX(-3,MIN(3,('3a Raw'!L20-$T3)/$T4))) | U20: =IF(T20="","",(T20-AVERAGE(T6:T1198))/(STDEV(T6:T1198)+1E-12)) | X20: =IF(U20="","",U20-($V$3*G20+$W$3)) | Y20: =IF(X20="","",MAX(-3,MIN(3,(X20-$X3)/$X4))) | Z20: =IF(Y20="","",(Y20-AVERAGE(Y6:Y1198))/(STDEV(Y6:Y1198)+1E-12))
A21: BBG009KG1750 | B21: =IF('3a Raw'!C21="","",MAX(-3,MIN(3,('3a Raw'!C21-$B3)/$B4))) | C21: =IF(B21="","",(B21-AVERAGE(B6:B1198))/(STDEV(B6:B1198)+1E-12)) | D21: =IF('3a Raw'!D21="","",MAX(-3,MIN(3,('3a Raw'!D21-$D3)/$D4))) | E21: =IF(D21="","",(D21-AVERAGE(D6:D1198))/(STDEV(D6:D1198)+1E-12)) | F21: =IF('3a Raw'!E21="","",MAX(-3,MIN(3,('3a Raw'!E21-$F3)/$F4))) | G21: =IF(F21="","",(F21-AVERAGE(F6:F1198))/(STDEV(F6:F1198)+1E-12)) | H21: =IF('3a Raw'!F21="","",MAX(-3,MIN(3,('3a Raw'!F21-$H3)/$H4))) | I21: =IF(H21="","",(H21-AVERAGE(H6:H1198))/(STDEV(H6:H1198)+1E-12)) | J21: =IF('3a Raw'!G21="","",MAX(-3,MIN(3,('3a Raw'!G21-$J3)/$J4))) | K21: =IF(J21="","",(J21-AVERAGE(J6:J1198))/(STDEV(J6:J1198)+1E-12)) | L21: =IF('3a Raw'!H21="","",MAX(-3,MIN(3,('3a Raw'!H21-$L3)/$L4))) | M21: =IF(L21="","",(L21-AVERAGE(L6:L1198))/(STDEV(L6:L1198)+1E-12)) | N21: =IF('3a Raw'!I21="","",MAX(-3,MIN(3,('3a Raw'!I21-$N3)/$N4))) | O21: =IF(N21="","",(N21-AVERAGE(N6:N1198))/(STDEV(N6:N1198)+1E-12)) | P21: =IF('3a Raw'!J21="","",MAX(-3,MIN(3,('3a Raw'!J21-$P3)/$P4))) | Q21: =IF(P21="","",(P21-AVERAGE(P6:P1198))/(STDEV(P6:P1198)+1E-12)) | R21: =IF('3a Raw'!K21="","",MAX(-3,MIN(3,('3a Raw'!K21-$R3)/$R4))) | S21: =IF(R21="","",(R21-AVERAGE(R6:R1198))/(STDEV(R6:R1198)+1E-12)) | T21: =IF('3a Raw'!L21="","",MAX(-3,MIN(3,('3a Raw'!L21-$T3)/$T4))) | U21: =IF(T21="","",(T21-AVERAGE(T6:T1198))/(STDEV(T6:T1198)+1E-12)) | X21: =IF(U21="","",U21-($V$3*G21+$W$3)) | Y21: =IF(X21="","",MAX(-3,MIN(3,(X21-$X3)/$X4))) | Z21: =IF(Y21="","",(Y21-AVERAGE(Y6:Y1198))/(STDEV(Y6:Y1198)+1E-12))
A22: acn | B22: =IF('3a Raw'!C22="","",MAX(-3,MIN(3,('3a Raw'!C22-$B3)/$B4))) | C22: =IF(B22="","",(B22-AVERAGE(B6:B1198))/(STDEV(B6:B1198)+1E-12)) | D22: =IF('3a Raw'!D22="","",MAX(-3,MIN(3,('3a Raw'!D22-$D3)/$D4))) | E22: =IF(D22="","",(D22-AVERAGE(D6:D1198))/(STDEV(D6:D1198)+1E-12)) | F22: =IF('3a Raw'!E22="","",MAX(-3,MIN(3,('3a Raw'!E22-$F3)/$F4))) | G22: =IF(F22="","",(F22-AVERAGE(F6:F1198))/(STDEV(F6:F1198)+1E-12)) | H22: =IF('3a Raw'!F22="","",MAX(-3,MIN(3,('3a Raw'!F22-$H3)/$H4))) | I22: =IF(H22="","",(H22-AVERAGE(H6:H1198))/(STDEV(H6:H1198)+1E-12)) | J22: =IF('3a Raw'!G22="","",MAX(-3,MIN(3,('3a Raw'!G22-$J3)/$J4))) | K22: =IF(J22="","",(J22-AVERAGE(J6:J1198))/(STDEV(J6:J1198)+1E-12)) | L22: =IF('3a Raw'!H22="","",MAX(-3,MIN(3,('3a Raw'!H22-$L3)/$L4))) | M22: =IF(L22="","",(L22-AVERAGE(L6:L1198))/(STDEV(L6:L1198)+1E-12)) | N22: =IF('3a Raw'!I22="","",MAX(-3,MIN(3,('3a Raw'!I22-$N3)/$N4))) | O22: =IF(N22="","",(N22-AVERAGE(N6:N1198))/(STDEV(N6:N1198)+1E-12)) | P22: =IF('3a Raw'!J22="","",MAX(-3,MIN(3,('3a Raw'!J22-$P3)/$P4))) | Q22: =IF(P22="","",(P22-AVERAGE(P6:P1198))/(STDEV(P6:P1198)+1E-12)) | R22: =IF('3a Raw'!K22="","",MAX(-3,MIN(3,('3a Raw'!K22-$R3)/$R4))) | S22: =IF(R22="","",(R22-AVERAGE(R6:R1198))/(STDEV(R6:R1198)+1E-12)) | T22: =IF('3a Raw'!L22="","",MAX(-3,MIN(3,('3a Raw'!L22-$T3)/$T4))) | U22: =IF(T22="","",(T22-AVERAGE(T6:T1198))/(STDEV(T6:T1198)+1E-12)) | X22: =IF(U22="","",U22-($V$3*G22+$W$3)) | Y22: =IF(X22="","",MAX(-3,MIN(3,(X22-$X3)/$X4))) | Z22: =IF(Y22="","",(Y22-AVERAGE(Y6:Y1198))/(STDEV(Y6:Y1198)+1E-12))
A23: BBG000KF9J02 | B23: =IF('3a Raw'!C23="","",MAX(-3,MIN(3,('3a Raw'!C23-$B3)/$B4))) | C23: =IF(B23="","",(B23-AVERAGE(B6:B1198))/(STDEV(B6:B1198)+1E-12)) | D23: =IF('3a Raw'!D23="","",MAX(-3,MIN(3,('3a Raw'!D23-$D3)/$D4))) | E23: =IF(D23="","",(D23-AVERAGE(D6:D1198))/(STDEV(D6:D1198)+1E-12)) | F23: =IF('3a Raw'!E23="","",MAX(-3,MIN(3,('3a Raw'!E23-$F3)/$F4))) | G23: =IF(F23="","",(F23-AVERAGE(F6:F1198))/(STDEV(F6:F1198)+1E-12)) | H23: =IF('3a Raw'!F23="","",MAX(-3,MIN(3,('3a Raw'!F23-$H3)/$H4))) | I23: =IF(H23="","",(H23-AVERAGE(H6:H1198))/(STDEV(H6:H1198)+1E-12)) | J23: =IF('3a Raw'!G23="","",MAX(-3,MIN(3,('3a Raw'!G23-$J3)/$J4))) | K23: =IF(J23="","",(J23-AVERAGE(J6:J1198))/(STDEV(J6:J1198)+1E-12)) | L23: =IF('3a Raw'!H23="","",MAX(-3,MIN(3,('3a Raw'!H23-$L3)/$L4))) | M23: =IF(L23="","",(L23-AVERAGE(L6:L1198))/(STDEV(L6:L1198)+1E-12)) | N23: =IF('3a Raw'!I23="","",MAX(-3,MIN(3,('3a Raw'!I23-$N3)/$N4))) | O23: =IF(N23="","",(N23-AVERAGE(N6:N1198))/(STDEV(N6:N1198)+1E-12)) | P23: =IF('3a Raw'!J23="","",MAX(-3,MIN(3,('3a Raw'!J23-$P3)/$P4))) | Q23: =IF(P23="","",(P23-AVERAGE(P6:P1198))/(STDEV(P6:P1198)+1E-12)) | R23: =IF('3a Raw'!K23="","",MAX(-3,MIN(3,('3a Raw'!K23-$R3)/$R4))) | S23: =IF(R23="","",(R23-AVERAGE(R6:R1198))/(STDEV(R6:R1198)+1E-12)) | T23: =IF('3a Raw'!L23="","",MAX(-3,MIN(3,('3a Raw'!L23-$T3)/$T4))) | U23: =IF(T23="","",(T23-AVERAGE(T6:T1198))/(STDEV(T6:T1198)+1E-12)) | X23: =IF(U23="","",U23-($V$3*G23+$W$3)) | Y23: =IF(X23="","",MAX(-3,MIN(3,(X23-$X3)/$X4))) | Z23: =IF(Y23="","",(Y23-AVERAGE(Y6:Y1198))/(STDEV(Y6:Y1198)+1E-12))
A24: BBG000BB5006 | B24: =IF('3a Raw'!C24="","",MAX(-3,MIN(3,('3a Raw'!C24-$B3)/$B4))) | C24: =IF(B24="","",(B24-AVERAGE(B6:B1198))/(STDEV(B6:B1198)+1E-12)) | D24: =IF('3a Raw'!D24="","",MAX(-3,MIN(3,('3a Raw'!D24-$D3)/$D4))) | E24: =IF(D24="","",(D24-AVERAGE(D6:D1198))/(STDEV(D6:D1198)+1E-12)) | F24: =IF('3a Raw'!E24="","",MAX(-3,MIN(3,('3a Raw'!E24-$F3)/$F4))) | G24: =IF(F24="","",(F24-AVERAGE(F6:F1198))/(STDEV(F6:F1198)+1E-12)) | H24: =IF('3a Raw'!F24="","",MAX(-3,MIN(3,('3a Raw'!F24-$H3)/$H4))) | I24: =IF(H24="","",(H24-AVERAGE(H6:H1198))/(STDEV(H6:H1198)+1E-12)) | J24: =IF('3a Raw'!G24="","",MAX(-3,MIN(3,('3a Raw'!G24-$J3)/$J4))) | K24: =IF(J24="","",(J24-AVERAGE(J6:J1198))/(STDEV(J6:J1198)+1E-12)) | L24: =IF('3a Raw'!H24="","",MAX(-3,MIN(3,('3a Raw'!H24-$L3)/$L4))) | M24: =IF(L24="","",(L24-AVERAGE(L6:L1198))/(STDEV(L6:L1198)+1E-12)) | N24: =IF('3a Raw'!I24="","",MAX(-3,MIN(3,('3a Raw'!I24-$N3)/$N4))) | O24: =IF(N24="","",(N24-AVERAGE(N6:N1198))/(STDEV(N6:N1198)+1E-12)) | P24: =IF('3a Raw'!J24="","",MAX(-3,MIN(3,('3a Raw'!J24-$P3)/$P4))) | Q24: =IF(P24="","",(P24-AVERAGE(P6:P1198))/(STDEV(P6:P1198)+1E-12)) | R24: =IF('3a Raw'!K24="","",MAX(-3,MIN(3,('3a Raw'!K24-$R3)/$R4))) | S24: =IF(R24="","",(R24-AVERAGE(R6:R1198))/(STDEV(R6:R1198)+1E-12)) | T24: =IF('3a Raw'!L24="","",MAX(-3,MIN(3,('3a Raw'!L24-$T3)/$T4))) | U24: =IF(T24="","",(T24-AVERAGE(T6:T1198))/(STDEV(T6:T1198)+1E-12)) | X24: =IF(U24="","",U24-($V$3*G24+$W$3)) | Y24: =IF(X24="","",MAX(-3,MIN(3,(X24-$X3)/$X4))) | Z24: =IF(Y24="","",(Y24-AVERAGE(Y6:Y1198))/(STDEV(Y6:Y1198)+1E-12))
A25: BBG000BC9DK0 | B25: =IF('3a Raw'!C25="","",MAX(-3,MIN(3,('3a Raw'!C25-$B3)/$B4))) | C25: =IF(B25="","",(B25-AVERAGE(B6:B1198))/(STDEV(B6:B1198)+1E-12)) | D25: =IF('3a Raw'!D25="","",MAX(-3,MIN(3,('3a Raw'!D25-$D3)/$D4))) | E25: =IF(D25="","",(D25-AVERAGE(D6:D1198))/(STDEV(D6:D1198)+1E-12)) | F25: =IF('3a Raw'!E25="","",MAX(-3,MIN(3,('3a Raw'!E25-$F3)/$F4))) | G25: =IF(F25="","",(F25-AVERAGE(F6:F1198))/(STDEV(F6:F1198)+1E-12)) | H25: =IF('3a Raw'!F25="","",MAX(-3,MIN(3,('3a Raw'!F25-$H3)/$H4))) | I25: =IF(H25="","",(H25-AVERAGE(H6:H1198))/(STDEV(H6:H1198)+1E-12)) | J25: =IF('3a Raw'!G25="","",MAX(-3,MIN(3,('3a Raw'!G25-$J3)/$J4))) | K25: =IF(J25="","",(J25-AVERAGE(J6:J1198))/(STDEV(J6:J1198)+1E-12)) | L25: =IF('3a Raw'!H25="","",MAX(-3,MIN(3,('3a Raw'!H25-$L3)/$L4))) | M25: =IF(L25="","",(L25-AVERAGE(L6:L1198))/(STDEV(L6:L1198)+1E-12)) | N25: =IF('3a Raw'!I25="","",MAX(-3,MIN(3,('3a Raw'!I25-$N3)/$N4))) | O25: =IF(N25="","",(N25-AVERAGE(N6:N1198))/(STDEV(N6:N1198)+1E-12)) | P25: =IF('3a Raw'!J25="","",MAX(-3,MIN(3,('3a Raw'!J25-$P3)/$P4))) | Q25: =IF(P25="","",(P25-AVERAGE(P6:P1198))/(STDEV(P6:P1198)+1E-12)) | R25: =IF('3a Raw'!K25="","",MAX(-3,MIN(3,('3a Raw'!K25-$R3)/$R4))) | S25: =IF(R25="","",(R25-AVERAGE(R6:R1198))/(STDEV(R6:R1198)+1E-12)) | T25: =IF('3a Raw'!L25="","",MAX(-3,MIN(3,('3a Raw'!L25-$T3)/$T4))) | U25: =IF(T25="","",(T25-AVERAGE(T6:T1198))/(STDEV(T6:T1198)+1E-12)) | X25: =IF(U25="","",U25-($V$3*G25+$W$3)) | Y25: =IF(X25="","",MAX(-3,MIN(3,(X25-$X3)/$X4))) | Z25: =IF(Y25="","",(Y25-AVERAGE(Y6:Y1198))/(STDEV(Y6:Y1198)+1E-12))
A26: BBG00RBFBL50 | B26: =IF('3a Raw'!C26="","",MAX(-3,MIN(3,('3a Raw'!C26-$B3)/$B4))) | C26: =IF(B26="","",(B26-AVERAGE(B6:B1198))/(STDEV(B6:B1198)+1E-12)) | D26: =IF('3a Raw'!D26="","",MAX(-3,MIN(3,('3a Raw'!D26-$D3)/$D4))) | E26: =IF(D26="","",(D26-AVERAGE(D6:D1198))/(STDEV(D6:D1198)+1E-12)) | F26: =IF('3a Raw'!E26="","",MAX(-3,MIN(3,('3a Raw'!E26-$F3)/$F4))) | G26: =IF(F26="","",(F26-AVERAGE(F6:F1198))/(STDEV(F6:F1198)+1E-12)) | H26: =IF('3a Raw'!F26="","",MAX(-3,MIN(3,('3a Raw'!F26-$H3)/$H4))) | I26: =IF(H26="","",(H26-AVERAGE(H6:H1198))/(STDEV(H6:H1198)+1E-12)) | J26: =IF('3a Raw'!G26="","",MAX(-3,MIN(3,('3a Raw'!G26-$J3)/$J4))) | K26: =IF(J26="","",(J26-AVERAGE(J6:J1198))/(STDEV(J6:J1198)+1E-12)) | L26: =IF('3a Raw'!H26="","",MAX(-3,MIN(3,('3a Raw'!H26-$L3)/$L4))) | M26: =IF(L26="","",(L26-AVERAGE(L6:L1198))/(STDEV(L6:L1198)+1E-12)) | N26: =IF('3a Raw'!I26="","",MAX(-3,MIN(3,('3a Raw'!I26-$N3)/$N4))) | O26: =IF(N26="","",(N26-AVERAGE(N6:N1198))/(STDEV(N6:N1198)+1E-12)) | P26: =IF('3a Raw'!J26="","",MAX(-3,MIN(3,('3a Raw'!J26-$P3)/$P4))) | Q26: =IF(P26="","",(P26-AVERAGE(P6:P1198))/(STDEV(P6:P1198)+1E-12)) | R26: =IF('3a Raw'!K26="","",MAX(-3,MIN(3,('3a Raw'!K26-$R3)/$R4))) | S26: =IF(R26="","",(R26-AVERAGE(R6:R1198))/(STDEV(R6:R1198)+1E-12)) | T26: =IF('3a Raw'!L26="","",MAX(-3,MIN(3,('3a Raw'!L26-$T3)/$T4))) | U26: =IF(T26="","",(T26-AVERAGE(T6:T1198))/(STDEV(T6:T1198)+1E-12)) | X26: =IF(U26="","",U26-($V$3*G26+$W$3)) | Y26: =IF(X26="","",MAX(-3,MIN(3,(X26-$X3)/$X4))) | Z26: =IF(Y26="","",(Y26-AVERAGE(Y6:Y1198))/(STDEV(Y6:Y1198)+1E-12))
A27: BBG000BB6G37 | B27: =IF('3a Raw'!C27="","",MAX(-3,MIN(3,('3a Raw'!C27-$B3)/$B4))) | C27: =IF(B27="","",(B27-AVERAGE(B6:B1198))/(STDEV(B6:B1198)+1E-12)) | D27: =IF('3a Raw'!D27="","",MAX(-3,MIN(3,('3a Raw'!D27-$D3)/$D4))) | E27: =IF(D27="","",(D27-AVERAGE(D6:D1198))/(STDEV(D6:D1198)+1E-12)) | F27: =IF('3a Raw'!E27="","",MAX(-3,MIN(3,('3a Raw'!E27-$F3)/$F4))) | G27: =IF(F27="","",(F27-AVERAGE(F6:F1198))/(STDEV(F6:F1198)+1E-12)) | H27: =IF('3a Raw'!F27="","",MAX(-3,MIN(3,('3a Raw'!F27-$H3)/$H4))) | I27: =IF(H27="","",(H27-AVERAGE(H6:H1198))/(STDEV(H6:H1198)+1E-12)) | J27: =IF('3a Raw'!G27="","",MAX(-3,MIN(3,('3a Raw'!G27-$J3)/$J4))) | K27: =IF(J27="","",(J27-AVERAGE(J6:J1198))/(STDEV(J6:J1198)+1E-12)) | L27: =IF('3a Raw'!H27="","",MAX(-3,MIN(3,('3a Raw'!H27-$L3)/$L4))) | M27: =IF(L27="","",(L27-AVERAGE(L6:L1198))/(STDEV(L6:L1198)+1E-12)) | N27: =IF('3a Raw'!I27="","",MAX(-3,MIN(3,('3a Raw'!I27-$N3)/$N4))) | O27: =IF(N27="","",(N27-AVERAGE(N6:N1198))/(STDEV(N6:N1198)+1E-12)) | P27: =IF('3a Raw'!J27="","",MAX(-3,MIN(3,('3a Raw'!J27-$P3)/$P4))) | Q27: =IF(P27="","",(P27-AVERAGE(P6:P1198))/(STDEV(P6:P1198)+1E-12)) | R27: =IF('3a Raw'!K27="","",MAX(-3,MIN(3,('3a Raw'!K27-$R3)/$R4))) | S27: =IF(R27="","",(R27-AVERAGE(R6:R1198))/(STDEV(R6:R1198)+1E-12)) | T27: =IF('3a Raw'!L27="","",MAX(-3,MIN(3,('3a Raw'!L27-$T3)/$T4))) | U27: =IF(T27="","",(T27-AVERAGE(T6:T1198))/(STDEV(T6:T1198)+1E-12)) | X27: =IF(U27="","",U27-($V$3*G27+$W$3)) | Y27: =IF(X27="","",MAX(-3,MIN(3,(X27-$X3)/$X4))) | Z27: =IF(Y27="","",(Y27-AVERAGE(Y6:Y1198))/(STDEV(Y6:Y1198)+1E-12))
A28: BBG000BB6WG8 | B28: =IF('3a Raw'!C28="","",MAX(-3,MIN(3,('3a Raw'!C28-$B3)/$B4))) | C28: =IF(B28="","",(B28-AVERAGE(B6:B1198))/(STDEV(B6:B1198)+1E-12)) | D28: =IF('3a Raw'!D28="","",MAX(-3,MIN(3,('3a Raw'!D28-$D3)/$D4))) | E28: =IF(D28="","",(D28-AVERAGE(D6:D1198))/(STDEV(D6:D1198)+1E-12)) | F28: =IF('3a Raw'!E28="","",MAX(-3,MIN(3,('3a Raw'!E28-$F3)/$F4))) | G28: =IF(F28="","",(F28-AVERAGE(F6:F1198))/(STDEV(F6:F1198)+1E-12)) | H28: =IF('3a Raw'!F28="","",MAX(-3,MIN(3,('3a Raw'!F28-$H3)/$H4))) | I28: =IF(H28="","",(H28-AVERAGE(H6:H1198))/(STDEV(H6:H1198)+1E-12)) | J28: =IF('3a Raw'!G28="","",MAX(-3,MIN(3,('3a Raw'!G28-$J3)/$J4))) | K28: =IF(J28="","",(J28-AVERAGE(J6:J1198))/(STDEV(J6:J1198)+1E-12)) | L28: =IF('3a Raw'!H28="","",MAX(-3,MIN(3,('3a Raw'!H28-$L3)/$L4))) | M28: =IF(L28="","",(L28-AVERAGE(L6:L1198))/(STDEV(L6:L1198)+1E-12)) | N28: =IF('3a Raw'!I28="","",MAX(-3,MIN(3,('3a Raw'!I28-$N3)/$N4))) | O28: =IF(N28="","",(N28-AVERAGE(N6:N1198))/(STDEV(N6:N1198)+1E-12)) | P28: =IF('3a Raw'!J28="","",MAX(-3,MIN(3,('3a Raw'!J28-$P3)/$P4))) | Q28: =IF(P28="","",(P28-AVERAGE(P6:P1198))/(STDEV(P6:P1198)+1E-12)) | R28: =IF('3a Raw'!K28="","",MAX(-3,MIN(3,('3a Raw'!K28-$R3)/$R4))) | S28: =IF(R28="","",(R28-AVERAGE(R6:R1198))/(STDEV(R6:R1198)+1E-12)) | T28: =IF('3a Raw'!L28="","",MAX(-3,MIN(3,('3a Raw'!L28-$T3)/$T4))) | U28: =IF(T28="","",(T28-AVERAGE(T6:T1198))/(STDEV(T6:T1198)+1E-12)) | X28: =IF(U28="","",U28-($V$3*G28+$W$3)) | Y28: =IF(X28="","",MAX(-3,MIN(3,(X28-$X3)/$X4))) | Z28: =IF(Y28="","",(Y28-AVERAGE(Y6:Y1198))/(STDEV(Y6:Y1198)+1E-12))
A29: BBG000JG0547 | B29: =IF('3a Raw'!C29="","",MAX(-3,MIN(3,('3a Raw'!C29-$B3)/$B4))) | C29: =IF(B29="","",(B29-AVERAGE(B6:B1198))/(STDEV(B6:B1198)+1E-12)) | D29: =IF('3a Raw'!D29="","",MAX(-3,MIN(3,('3a Raw'!D29-$D3)/$D4))) | E29: =IF(D29="","",(D29-AVERAGE(D6:D1198))/(STDEV(D6:D1198)+1E-12)) | F29: =IF('3a Raw'!E29="","",MAX(-3,MIN(3,('3a Raw'!E29-$F3)/$F4))) | G29: =IF(F29="","",(F29-AVERAGE(F6:F1198))/(STDEV(F6:F1198)+1E-12)) | H29: =IF('3a Raw'!F29="","",MAX(-3,MIN(3,('3a Raw'!F29-$H3)/$H4))) | I29: =IF(H29="","",(H29-AVERAGE(H6:H1198))/(STDEV(H6:H1198)+1E-12)) | J29: =IF('3a Raw'!G29="","",MAX(-3,MIN(3,('3a Raw'!G29-$J3)/$J4))) | K29: =IF(J29="","",(J29-AVERAGE(J6:J1198))/(STDEV(J6:J1198)+1E-12)) | L29: =IF('3a Raw'!H29="","",MAX(-3,MIN(3,('3a Raw'!H29-$L3)/$L4))) | M29: =IF(L29="","",(L29-AVERAGE(L6:L1198))/(STDEV(L6:L1198)+1E-12)) | N29: =IF('3a Raw'!I29="","",MAX(-3,MIN(3,('3a Raw'!I29-$N3)/$N4))) | O29: =IF(N29="","",(N29-AVERAGE(N6:N1198))/(STDEV(N6:N1198)+1E-12)) | P29: =IF('3a Raw'!J29="","",MAX(-3,MIN(3,('3a Raw'!J29-$P3)/$P4))) | Q29: =IF(P29="","",(P29-AVERAGE(P6:P1198))/(STDEV(P6:P1198)+1E-12)) | R29: =IF('3a Raw'!K29="","",MAX(-3,MIN(3,('3a Raw'!K29-$R3)/$R4))) | S29: =IF(R29="","",(R29-AVERAGE(R6:R1198))/(STDEV(R6:R1198)+1E-12)) | T29: =IF('3a Raw'!L29="","",MAX(-3,MIN(3,('3a Raw'!L29-$T3)/$T4))) | U29: =IF(T29="","",(T29-AVERAGE(T6:T1198))/(STDEV(T6:T1198)+1E-12)) | X29: =IF(U29="","",U29-($V$3*G29+$W$3)) | Y29: =IF(X29="","",MAX(-3,MIN(3,(X29-$X3)/$X4))) | Z29: =IF(Y29="","",(Y29-AVERAGE(Y6:Y1198))/(STDEV(Y6:Y1198)+1E-12))
A30: BBG000BM7HL0 | B30: =IF('3a Raw'!C30="","",MAX(-3,MIN(3,('3a Raw'!C30-$B3)/$B4))) | C30: =IF(B30="","",(B30-AVERAGE(B6:B1198))/(STDEV(B6:B1198)+1E-12)) | D30: =IF('3a Raw'!D30="","",MAX(-3,MIN(3,('3a Raw'!D30-$D3)/$D4))) | E30: =IF(D30="","",(D30-AVERAGE(D6:D1198))/(STDEV(D6:D1198)+1E-12)) | F30: =IF('3a Raw'!E30="","",MAX(-3,MIN(3,('3a Raw'!E30-$F3)/$F4))) | G30: =IF(F30="","",(F30-AVERAGE(F6:F1198))/(STDEV(F6:F1198)+1E-12)) | H30: =IF('3a Raw'!F30="","",MAX(-3,MIN(3,('3a Raw'!F30-$H3)/$H4))) | I30: =IF(H30="","",(H30-AVERAGE(H6:H1198))/(STDEV(H6:H1198)+1E-12)) | J30: =IF('3a Raw'!G30="","",MAX(-3,MIN(3,('3a Raw'!G30-$J3)/$J4))) | K30: =IF(J30="","",(J30-AVERAGE(J6:J1198))/(STDEV(J6:J1198)+1E-12)) | L30: =IF('3a Raw'!H30="","",MAX(-3,MIN(3,('3a Raw'!H30-$L3)/$L4))) | M30: =IF(L30="","",(L30-AVERAGE(L6:L1198))/(STDEV(L6:L1198)+1E-12)) | N30: =IF('3a Raw'!I30="","",MAX(-3,MIN(3,('3a Raw'!I30-$N3)/$N4))) | O30: =IF(N30="","",(N30-AVERAGE(N6:N1198))/(STDEV(N6:N1198)+1E-12)) | P30: =IF('3a Raw'!J30="","",MAX(-3,MIN(3,('3a Raw'!J30-$P3)/$P4))) | Q30: =IF(P30="","",(P30-AVERAGE(P6:P1198))/(STDEV(P6:P1198)+1E-12)) | R30: =IF('3a Raw'!K30="","",MAX(-3,MIN(3,('3a Raw'!K30-$R3)/$R4))) | S30: =IF(R30="","",(R30-AVERAGE(R6:R1198))/(STDEV(R6:R1198)+1E-12)) | T30: =IF('3a Raw'!L30="","",MAX(-3,MIN(3,('3a Raw'!L30-$T3)/$T4))) | U30: =IF(T30="","",(T30-AVERAGE(T6:T1198))/(STDEV(T6:T1198)+1E-12)) | X30: =IF(U30="","",U30-($V$3*G30+$W$3)) | Y30: =IF(X30="","",MAX(-3,MIN(3,(X30-$X3)/$X4))) | Z30: =IF(Y30="","",(Y30-AVERAGE(Y6:Y1198))/(STDEV(Y6:Y1198)+1E-12))
A31: BBG000BP9WJ1 | B31: =IF('3a Raw'!C31="","",MAX(-3,MIN(3,('3a Raw'!C31-$B3)/$B4))) | C31: =IF(B31="","",(B31-AVERAGE(B6:B1198))/(STDEV(B6:B1198)+1E-12)) | D31: =IF('3a Raw'!D31="","",MAX(-3,MIN(3,('3a Raw'!D31-$D3)/$D4))) | E31: =IF(D31="","",(D31-AVERAGE(D6:D1198))/(STDEV(D6:D1198)+1E-12)) | F31: =IF('3a Raw'!E31="","",MAX(-3,MIN(3,('3a Raw'!E31-$F3)/$F4))) | G31: =IF(F31="","",(F31-AVERAGE(F6:F1198))/(STDEV(F6:F1198)+1E-12)) | H31: =IF('3a Raw'!F31="","",MAX(-3,MIN(3,('3a Raw'!F31-$H3)/$H4))) | I31: =IF(H31="","",(H31-AVERAGE(H6:H1198))/(STDEV(H6:H1198)+1E-12)) | J31: =IF('3a Raw'!G31="","",MAX(-3,MIN(3,('3a Raw'!G31-$J3)/$J4))) | K31: =IF(J31="","",(J31-AVERAGE(J6:J1198))/(STDEV(J6:J1198)+1E-12)) | L31: =IF('3a Raw'!H31="","",MAX(-3,MIN(3,('3a Raw'!H31-$L3)/$L4))) | M31: =IF(L31="","",(L31-AVERAGE(L6:L1198))/(STDEV(L6:L1198)+1E-12)) | N31: =IF('3a Raw'!I31="","",MAX(-3,MIN(3,('3a Raw'!I31-$N3)/$N4))) | O31: =IF(N31="","",(N31-AVERAGE(N6:N1198))/(STDEV(N6:N1198)+1E-12)) | P31: =IF('3a Raw'!J31="","",MAX(-3,MIN(3,('3a Raw'!J31-$P3)/$P4))) | Q31: =IF(P31="","",(P31-AVERAGE(P6:P1198))/(STDEV(P6:P1198)+1E-12)) | R31: =IF('3a Raw'!K31="","",MAX(-3,MIN(3,('3a Raw'!K31-$R3)/$R4))) | S31: =IF(R31="","",(R31-AVERAGE(R6:R1198))/(STDEV(R6:R1198)+1E-12)) | T31: =IF('3a Raw'!L31="","",MAX(-3,MIN(3,('3a Raw'!L31-$T3)/$T4))) | U31: =IF(T31="","",(T31-AVERAGE(T6:T1198))/(STDEV(T6:T1198)+1E-12)) | X31: =IF(U31="","",U31-($V$3*G31+$W$3)) | Y31: =IF(X31="","",MAX(-3,MIN(3,(X31-$X3)/$X4))) | Z31: =IF(Y31="","",(Y31-AVERAGE(Y6:Y1198))/(STDEV(Y6:Y1198)+1E-12))
A32: BBG000B9X8C0 | B32: =IF('3a Raw'!C32="","",MAX(-3,MIN(3,('3a Raw'!C32-$B3)/$B4))) | C32: =IF(B32="","",(B32-AVERAGE(B6:B1198))/(STDEV(B6:B1198)+1E-12)) | D32: =IF('3a Raw'!D32="","",MAX(-3,MIN(3,('3a Raw'!D32-$D3)/$D4))) | E32: =IF(D32="","",(D32-AVERAGE(D6:D1198))/(STDEV(D6:D1198)+1E-12)) | F32: =IF('3a Raw'!E32="","",MAX(-3,MIN(3,('3a Raw'!E32-$F3)/$F4))) | G32: =IF(F32="","",(F32-AVERAGE(F6:F1198))/(STDEV(F6:F1198)+1E-12)) | H32: =IF('3a Raw'!F32="","",MAX(-3,MIN(3,('3a Raw'!F32-$H3)/$H4))) | I32: =IF(H32="","",(H32-AVERAGE(H6:H1198))/(STDEV(H6:H1198)+1E-12)) | J32: =IF('3a Raw'!G32="","",MAX(-3,MIN(3,('3a Raw'!G32-$J3)/$J4))) | K32: =IF(J32="","",(J32-AVERAGE(J6:J1198))/(STDEV(J6:J1198)+1E-12)) | L32: =IF('3a Raw'!H32="","",MAX(-3,MIN(3,('3a Raw'!H32-$L3)/$L4))) | M32: =IF(L32="","",(L32-AVERAGE(L6:L1198))/(STDEV(L6:L1198)+1E-12)) | N32: =IF('3a Raw'!I32="","",MAX(-3,MIN(3,('3a Raw'!I32-$N3)/$N4))) | O32: =IF(N32="","",(N32-AVERAGE(N6:N1198))/(STDEV(N6:N1198)+1E-12)) | P32: =IF('3a Raw'!J32="","",MAX(-3,MIN(3,('3a Raw'!J32-$P3)/$P4))) | Q32: =IF(P32="","",(P32-AVERAGE(P6:P1198))/(STDEV(P6:P1198)+1E-12)) | R32: =IF('3a Raw'!K32="","",MAX(-3,MIN(3,('3a Raw'!K32-$R3)/$R4))) | S32: =IF(R32="","",(R32-AVERAGE(R6:R1198))/(STDEV(R6:R1198)+1E-12)) | T32: =IF('3a Raw'!L32="","",MAX(-3,MIN(3,('3a Raw'!L32-$T3)/$T4))) | U32: =IF(T32="","",(T32-AVERAGE(T6:T1198))/(STDEV(T6:T1198)+1E-12)) | X32: =IF(U32="","",U32-($V$3*G32+$W$3)) | Y32: =IF(X32="","",MAX(-3,MIN(3,(X32-$X3)/$X4))) | Z32: =IF(Y32="","",(Y32-AVERAGE(Y6:Y1198))/(STDEV(Y6:Y1198)+1E-12))
A33: BBG000FKMP26 | B33: =IF('3a Raw'!C33="","",MAX(-3,MIN(3,('3a Raw'!C33-$B3)/$B4))) | C33: =IF(B33="","",(B33-AVERAGE(B6:B1198))/(STDEV(B6:B1198)+1E-12)) | D33: =IF('3a Raw'!D33="","",MAX(-3,MIN(3,('3a Raw'!D33-$D3)/$D4))) | E33: =IF(D33="","",(D33-AVERAGE(D6:D1198))/(STDEV(D6:D1198)+1E-12)) | F33: =IF('3a Raw'!E33="","",MAX(-3,MIN(3,('3a Raw'!E33-$F3)/$F4))) | G33: =IF(F33="","",(F33-AVERAGE(F6:F1198))/(STDEV(F6:F1198)+1E-12)) | H33: =IF('3a Raw'!F33="","",MAX(-3,MIN(3,('3a Raw'!F33-$H3)/$H4))) | I33: =IF(H33="","",(H33-AVERAGE(H6:H1198))/(STDEV(H6:H1198)+1E-12)) | J33: =IF('3a Raw'!G33="","",MAX(-3,MIN(3,('3a Raw'!G33-$J3)/$J4))) | K33: =IF(J33="","",(J33-AVERAGE(J6:J1198))/(STDEV(J6:J1198)+1E-12)) | L33: =IF('3a Raw'!H33="","",MAX(-3,MIN(3,('3a Raw'!H33-$L3)/$L4))) | M33: =IF(L33="","",(L33-AVERAGE(L6:L1198))/(STDEV(L6:L1198)+1E-12)) | N33: =IF('3a Raw'!I33="","",MAX(-3,MIN(3,('3a Raw'!I33-$N3)/$N4))) | O33: =IF(N33="","",(N33-AVERAGE(N6:N1198))/(STDEV(N6:N1198)+1E-12)) | P33: =IF('3a Raw'!J33="","",MAX(-3,MIN(3,('3a Raw'!J33-$P3)/$P4))) | Q33: =IF(P33="","",(P33-AVERAGE(P6:P1198))/(STDEV(P6:P1198)+1E-12)) | R33: =IF('3a Raw'!K33="","",MAX(-3,MIN(3,('3a Raw'!K33-$R3)/$R4))) | S33: =IF(R33="","",(R33-AVERAGE(R6:R1198))/(STDEV(R6:R1198)+1E-12)) | T33: =IF('3a Raw'!L33="","",MAX(-3,MIN(3,('3a Raw'!L33-$T3)/$T4))) | U33: =IF(T33="","",(T33-AVERAGE(T6:T1198))/(STDEV(T6:T1198)+1E-12)) | X33: =IF(U33="","",U33-($V$3*G33+$W$3)) | Y33: =IF(X33="","",MAX(-3,MIN(3,(X33-$X3)/$X4))) | Z33: =IF(Y33="","",(Y33-AVERAGE(Y6:Y1198))/(STDEV(Y6:Y1198)+1E-12))
A34: BBG000DLVDK3 | B34: =IF('3a Raw'!C34="","",MAX(-3,MIN(3,('3a Raw'!C34-$B3)/$B4))) | C34: =IF(B34="","",(B34-AVERAGE(B6:B1198))/(STDEV(B6:B1198)+1E-12)) | D34: =IF('3a Raw'!D34="","",MAX(-3,MIN(3,('3a Raw'!D34-$D3)/$D4))) | E34: =IF(D34="","",(D34-AVERAGE(D6:D1198))/(STDEV(D6:D1198)+1E-12)) | F34: =IF('3a Raw'!E34="","",MAX(-3,MIN(3,('3a Raw'!E34-$F3)/$F4))) | G34: =IF(F34="","",(F34-AVERAGE(F6:F1198))/(STDEV(F6:F1198)+1E-12)) | H34: =IF('3a Raw'!F34="","",MAX(-3,MIN(3,('3a Raw'!F34-$H3)/$H4))) | I34: =IF(H34="","",(H34-AVERAGE(H6:H1198))/(STDEV(H6:H1198)+1E-12)) | J34: =IF('3a Raw'!G34="","",MAX(-3,MIN(3,('3a Raw'!G34-$J3)/$J4))) | K34: =IF(J34="","",(J34-AVERAGE(J6:J1198))/(STDEV(J6:J1198)+1E-12)) | L34: =IF('3a Raw'!H34="","",MAX(-3,MIN(3,('3a Raw'!H34-$L3)/$L4))) | M34: =IF(L34="","",(L34-AVERAGE(L6:L1198))/(STDEV(L6:L1198)+1E-12)) | N34: =IF('3a Raw'!I34="","",MAX(-3,MIN(3,('3a Raw'!I34-$N3)/$N4))) | O34: =IF(N34="","",(N34-AVERAGE(N6:N1198))/(STDEV(N6:N1198)+1E-12)) | P34: =IF('3a Raw'!J34="","",MAX(-3,MIN(3,('3a Raw'!J34-$P3)/$P4))) | Q34: =IF(P34="","",(P34-AVERAGE(P6:P1198))/(STDEV(P6:P1198)+1E-12)) | R34: =IF('3a Raw'!K34="","",MAX(-3,MIN(3,('3a Raw'!K34-$R3)/$R4))) | S34: =IF(R34="","",(R34-AVERAGE(R6:R1198))/(STDEV(R6:R1198)+1E-12)) | T34: =IF('3a Raw'!L34="","",MAX(-3,MIN(3,('3a Raw'!L34-$T3)/$T4))) | U34: =IF(T34="","",(T34-AVERAGE(T6:T1198))/(STDEV(T6:T1198)+1E-12)) | X34: =IF(U34="","",U34-($V$3*G34+$W$3)) | Y34: =IF(X34="","",MAX(-3,MIN(3,(X34-$X3)/$X4))) | Z34: =IF(Y34="","",(Y34-AVERAGE(Y6:Y1198))/(STDEV(Y6:Y1198)+1E-12))
A35: BBG000BGXZB5 | B35: =IF('3a Raw'!C35="","",MAX(-3,MIN(3,('3a Raw'!C35-$B3)/$B4))) | C35: =IF(B35="","",(B35-AVERAGE(B6:B1198))/(STDEV(B6:B1198)+1E-12)) | D35: =IF('3a Raw'!D35="","",MAX(-3,MIN(3,('3a Raw'!D35-$D3)/$D4))) | E35: =IF(D35="","",(D35-AVERAGE(D6:D1198))/(STDEV(D6:D1198)+1E-12)) | F35: =IF('3a Raw'!E35="","",MAX(-3,MIN(3,('3a Raw'!E35-$F3)/$F4))) | G35: =IF(F35="","",(F35-AVERAGE(F6:F1198))/(STDEV(F6:F1198)+1E-12)) | H35: =IF('3a Raw'!F35="","",MAX(-3,MIN(3,('3a Raw'!F35-$H3)/$H4))) | I35: =IF(H35="","",(H35-AVERAGE(H6:H1198))/(STDEV(H6:H1198)+1E-12)) | J35: =IF('3a Raw'!G35="","",MAX(-3,MIN(3,('3a Raw'!G35-$J3)/$J4))) | K35: =IF(J35="","",(J35-AVERAGE(J6:J1198))/(STDEV(J6:J1198)+1E-12)) | L35: =IF('3a Raw'!H35="","",MAX(-3,MIN(3,('3a Raw'!H35-$L3)/$L4))) | M35: =IF(L35="","",(L35-AVERAGE(L6:L1198))/(STDEV(L6:L1198)+1E-12)) | N35: =IF('3a Raw'!I35="","",MAX(-3,MIN(3,('3a Raw'!I35-$N3)/$N4))) | O35: =IF(N35="","",(N35-AVERAGE(N6:N1198))/(STDEV(N6:N1198)+1E-12)) | P35: =IF('3a Raw'!J35="","",MAX(-3,MIN(3,('3a Raw'!J35-$P3)/$P4))) | Q35: =IF(P35="","",(P35-AVERAGE(P6:P1198))/(STDEV(P6:P1198)+1E-12)) | R35: =IF('3a Raw'!K35="","",MAX(-3,MIN(3,('3a Raw'!K35-$R3)/$R4))) | S35: =IF(R35="","",(R35-AVERAGE(R6:R1198))/(STDEV(R6:R1198)+1E-12)) | T35: =IF('3a Raw'!L35="","",MAX(-3,MIN(3,('3a Raw'!L35-$T3)/$T4))) | U35: =IF(T35="","",(T35-AVERAGE(T6:T1198))/(STDEV(T6:T1198)+1E-12)) | X35: =IF(U35="","",U35-($V$3*G35+$W$3)) | Y35: =IF(X35="","",MAX(-3,MIN(3,(X35-$X3)/$X4))) | Z35: =IF(Y35="","",(Y35-AVERAGE(Y6:Y1198))/(STDEV(Y6:Y1198)+1E-12))
A36: BBG000BB9KF2 | B36: =IF('3a Raw'!C36="","",MAX(-3,MIN(3,('3a Raw'!C36-$B3)/$B4))) | C36: =IF(B36="","",(B36-AVERAGE(B6:B1198))/(STDEV(B6:B1198)+1E-12)) | D36: =IF('3a Raw'!D36="","",MAX(-3,MIN(3,('3a Raw'!D36-$D3)/$D4))) | E36: =IF(D36="","",(D36-AVERAGE(D6:D1198))/(STDEV(D6:D1198)+1E-12)) | F36: =IF('3a Raw'!E36="","",MAX(-3,MIN(3,('3a Raw'!E36-$F3)/$F4))) | G36: =IF(F36="","",(F36-AVERAGE(F6:F1198))/(STDEV(F6:F1198)+1E-12)) | H36: =IF('3a Raw'!F36="","",MAX(-3,MIN(3,('3a Raw'!F36-$H3)/$H4))) | I36: =IF(H36="","",(H36-AVERAGE(H6:H1198))/(STDEV(H6:H1198)+1E-12)) | J36: =IF('3a Raw'!G36="","",MAX(-3,MIN(3,('3a Raw'!G36-$J3)/$J4))) | K36: =IF(J36="","",(J36-AVERAGE(J6:J1198))/(STDEV(J6:J1198)+1E-12)) | L36: =IF('3a Raw'!H36="","",MAX(-3,MIN(3,('3a Raw'!H36-$L3)/$L4))) | M36: =IF(L36="","",(L36-AVERAGE(L6:L1198))/(STDEV(L6:L1198)+1E-12)) | N36: =IF('3a Raw'!I36="","",MAX(-3,MIN(3,('3a Raw'!I36-$N3)/$N4))) | O36: =IF(N36="","",(N36-AVERAGE(N6:N1198))/(STDEV(N6:N1198)+1E-12)) | P36: =IF('3a Raw'!J36="","",MAX(-3,MIN(3,('3a Raw'!J36-$P3)/$P4))) | Q36: =IF(P36="","",(P36-AVERAGE(P6:P1198))/(STDEV(P6:P1198)+1E-12)) | R36: =IF('3a Raw'!K36="","",MAX(-3,MIN(3,('3a Raw'!K36-$R3)/$R4))) | S36: =IF(R36="","",(R36-AVERAGE(R6:R1198))/(STDEV(R6:R1198)+1E-12)) | T36: =IF('3a Raw'!L36="","",MAX(-3,MIN(3,('3a Raw'!L36-$T3)/$T4))) | U36: =IF(T36="","",(T36-AVERAGE(T6:T1198))/(STDEV(T6:T1198)+1E-12)) | X36: =IF(U36="","",U36-($V$3*G36+$W$3)) | Y36: =IF(X36="","",MAX(-3,MIN(3,(X36-$X3)/$X4))) | Z36: =IF(Y36="","",(Y36-AVERAGE(Y6:Y1198))/(STDEV(Y6:Y1198)+1E-12))
