Workbook

Sheet Inputs
A1: As-of date | B1: 45657
A3: Position | B3: Ticker | C3: Issuer | D3: Weight | E3: SpecificVar | F3: SV as-of
A4: BBG006G2JVL2 | B4: baba | C4: Alibaba Group Holding Ltd | D4: 0.2571858 | E4: 0.00030932331 | F4: 45657
A5: BBG009S39JX6 | B5: googl | C5: Alphabet Inc. | D5: 0.15938945 | E5: 0.00011978142 | F5: 45657
A6: BBG000BVPV84 | B6: amzn | C6: AMAZON COM INC | D6: 0.096888666 | E6: 0.00015787267 | F6: 45657
A8: Weight sum (sub-book of the full Soros book) | D8: =SUM(D4:D6)

Sheet Exposures
A1: Position | B1: Beta | C1: EarnYield | D1: Growth | E1: Leverage | F1: Liquidity | G1: Market | H1: Momentum | I1: NonLinSize | J1: ResidVol | K1: Size | L1: Value
A2: BBG006G2JVL2 | B2: -0.64663396 | C2: 1.0477699 | D2: 0 | E2: -0.5681394 | F2: 1.6746124 | G2: 1 | H2: -0.1239349 | I2: -1.0666178 | J2: 0.27371248 | K2: 2.6323043 | L2: 0.54131823
A3: BBG009S39JX6 | B3: 0.43313204 | C3: 0.24248475 | D3: 0 | E3: -0.66271326 | F3: 2.3277308 | G3: 1 | H3: 0.067267547 | I3: -1.4951459 | J3: -0.65243157 | K3: 2.6525068 | L3: -0.69240065
A4: BBG000BVPV84 | B4: 0.95069155 | C4: -0.32098519 | D4: 0 | E4: -0.42837724 | F4: 2.6153879 | G4: 1 | H4: 0.51026479 | I4: -1.4951459 | J4: -0.86389256 | K4: 2.6525068 | L4: -0.70724576
A6: Net exposure x_k (book) | B6: =SUMPRODUCT(B2:B4,Inputs!$D$4:$D$6) | C6: =SUMPRODUCT(C2:C4,Inputs!$D$4:$D$6) | D6: =SUMPRODUCT(D2:D4,Inputs!$D$4:$D$6) | E6: =SUMPRODUCT(E2:E4,Inputs!$D$4:$D$6) | F6: =SUMPRODUCT(F2:F4,Inputs!$D$4:$D$6) | G6: =SUMPRODUCT(G2:G4,Inputs!$D$4:$D$6) | H6: =SUMPRODUCT(H2:H4,Inputs!$D$4:$D$6) | I6: =SUMPRODUCT(I2:I4,Inputs!$D$4:$D$6) | ... L6: =SUMPRODUCT(L2:L4,Inputs!$D$4:$D$6)
A8: x_k BABA | B8: =B2*Inputs!$D$4 | C8: =C2*Inputs!$D$4 | D8: =D2*Inputs!$D$4 | E8: =E2*Inputs!$D$4 | F8: =F2*Inputs!$D$4 | G8: =G2*Inputs!$D$4 | H8: =H2*Inputs!$D$4 | I8: =I2*Inputs!$D$4 | ... L8: =L2*Inputs!$D$4
A9: x_k GOOGL | B9: =B3*Inputs!$D$5 | C9: =C3*Inputs!$D$5 | D9: =D3*Inputs!$D$5 | E9: =E3*Inputs!$D$5 | F9: =F3*Inputs!$D$5 | G9: =G3*Inputs!$D$5 | H9: =H3*Inputs!$D$5 | I9: =I3*Inputs!$D$5 | ... L9: =L3*Inputs!$D$5
A10: x_k AMZN | B10: =B4*Inputs!$D$6 | C10: =C4*Inputs!$D$6 | D10: =D4*Inputs!$D$6 | E10: =E4*Inputs!$D$6 | F10: =F4*Inputs!$D$6 | G10: =G4*Inputs!$D$6 | H10: =H4*Inputs!$D$6 | I10: =I4*Inputs!$D$6 | ... L10: =L4*Inputs!$D$6

Sheet FactorReturns
A1: Date | B1: Beta | C1: EarnYield | D1: Growth | E1: Leverage | F1: Liquidity | G1: Market | H1: Momentum | I1: NonLinSize | J1: ResidVol | K1: Size | L1: Value | M1: PnL HistFull | N1: PnL COVID2020 | O1: PnL Rates2022 | P1: PnL Selloff2018 | Q1: PnL BABA | R1: PnL GOOGL | S1: PnL AMZN
A2: 42461 | B2: 0.0040201682 | C2: -0.00024105114 | D2: -0.0016056291 | E2: -0.00090695098 | F2: -0.0019038476 | G2: 0.0048135795 | H2: 0.0041526108 | I2: -0.00040432701 | J2: -8.0922174e-05 | K2: 0.0032837905 | L2: -7.808784e-05 | M2: =SUMPRODUCT(Exposures!$B$6:$K$6,B2:K2) | N2: =IF(AND($A2>=DATE(2020,2,1),$A2<=DATE(2020,5,31)),$M2,"") | O2: =IF(AND($A2>=DATE(2022,1,1),$A2<=DATE(2022,10,31)),$M2,"") | P2: =IF(AND($A2>=DATE(2018,10,1),$A2<=DATE(2018,12,31)),$M2,"") | Q2: =SUMPRODUCT(Exposures!$B$8:$K$8,B2:K2) | R2: =SUMPRODUCT(Exposures!$B$9:$K$9,B2:K2) | S2: =SUMPRODUCT(Exposures!$B$10:$K$10,B2:K2)
A3: 42464 | B3: -0.0023869493 | C3: -0.0027659108 | D3: -0.012938379 | E3: -0.00059019741 | F3: 0.0015284468 | G3: -0.0042003591 | H3: -0.00066020065 | I3: 0.0030243456 | J3: 0.002134361 | K3: 0.0013865739 | L3: -0.0021271471 | M3: =SUMPRODUCT(Exposures!$B$6:$K$6,B3:K3) | N3: =IF(AND($A3>=DATE(2020,2,1),$A3<=DATE(2020,5,31)),$M3,"") | O3: =IF(AND($A3>=DATE(2022,1,1),$A3<=DATE(2022,10,31)),$M3,"") | P3: =IF(AND($A3>=DATE(2018,10,1),$A3<=DATE(2018,12,31)),$M3,"") | Q3: =SUMPRODUCT(Exposures!$B$8:$K$8,B3:K3) | R3: =SUMPRODUCT(Exposures!$B$9:$K$9,B3:K3) | S3: =SUMPRODUCT(Exposures!$B$10:$K$10,B3:K3)
A4: 42465 | B4: 0.0020349316 | C4: 0.00063516533 | D4: 0.0016879013 | E4: -0.00053363254 | F4: 0.0019413642 | G4: -0.01137724 | H4: 0.001784463 | I4: 0.001889793 | J4: -0.0024735022 | K4: -0.0038817496 | L4: -0.0035412161 | M4: =SUMPRODUCT(Exposures!$B$6:$K$6,B4:K4) | N4: =IF(AND($A4>=DATE(2020,2,1),$A4<=DATE(2020,5,31)),$M4,"") | O4: =IF(AND($A4>=DATE(2022,1,1),$A4<=DATE(2022,10,31)),$M4,"") | P4: =IF(AND($A4>=DATE(2018,10,1),$A4<=DATE(2018,12,31)),$M4,"") | Q4: =SUMPRODUCT(Exposures!$B$8:$K$8,B4:K4) | R4: =SUMPRODUCT(Exposures!$B$9:$K$9,B4:K4) | S4: =SUMPRODUCT(Exposures!$B$10:$K$10,B4:K4)
A5: 42466 | B5: 0.0085429858 | C5: -0.0029240642 | D5: -0.018802051 | E5: -0.0029646642 | F5: 0.00047263082 | G5: 0.012549222 | H5: 0.0024081542 | I5: -0.00036808141 | J5: 0.0039394949 | K5: 0.0034254012 | L5: -0.0036227778 | M5: =SUMPRODUCT(Exposures!$B$6:$K$6,B5:K5) | N5: =IF(AND($A5>=DATE(2020,2,1),$A5<=DATE(2020,5,31)),$M5,"") | O5: =IF(AND($A5>=DATE(2022,1,1),$A5<=DATE(2022,10,31)),$M5,"") | P5: =IF(AND($A5>=DATE(2018,10,1),$A5<=DATE(2018,12,31)),$M5,"") | Q5: =SUMPRODUCT(Exposures!$B$8:$K$8,B5:K5) | R5: =SUMPRODUCT(Exposures!$B$9:$K$9,B5:K5) | S5: =SUMPRODUCT(Exposures!$B$10:$K$10,B5:K5)
A6: 42467 | B6: -0.0070730737 | C6: 0.001570214 | D6: 0.020426357 | E6: -0.0022193787 | F6: -0.00015307946 | G6: -0.013868753 | H6: -0.0009906485 | I6: 1.0140219e-06 | J6: 0.0018571074 | K6: 0.0011660919 | L6: -0.0014950866 | M6: =SUMPRODUCT(Exposures!$B$6:$K$6,B6:K6) | N6: =IF(AND($A6>=DATE(2020,2,1),$A6<=DATE(2020,5,31)),$M6,"") | O6: =IF(AND($A6>=DATE(2022,1,1),$A6<=DATE(2022,10,31)),$M6,"") | P6: =IF(AND($A6>=DATE(2018,10,1),$A6<=DATE(2018,12,31)),$M6,"") | Q6: =SUMPRODUCT(Exposures!$B$8:$K$8,B6:K6) | R6: =SUMPRODUCT(Exposures!$B$9:$K$9,B6:K6) | S6: =SUMPRODUCT(Exposures!$B$10:$K$10,B6:K6)
A7: 42468 | B7: 0.0028731997 | C7: 0.00048250931 | D7: -0.015951981 | E7: 0.00040708939 | F7: -0.0060387042 | G7: 0.0047932587 | H7: 0.00099477354 | I7: 0.00094386362 | J7: 5.0445099e-05 | K7: 0.001974021 | L7: 0.0012149216 | M7: =SUMPRODUCT(Exposures!$B$6:$K$6,B7:K7) | N7: =IF(AND($A7>=DATE(2020,2,1),$A7<=DATE(2020,5,31)),$M7,"") | O7: =IF(AND($A7>=DATE(2022,1,1),$A7<=DATE(2022,10,31)),$M7,"") | P7: =IF(AND($A7>=DATE(2018,10,1),$A7<=DATE(2018,12,31)),$M7,"") | Q7: =SUMPRODUCT(Exposures!$B$8:$K$8,B7:K7) | R7: =SUMPRODUCT(Exposures!$B$9:$K$9,B7:K7) | S7: =SUMPRODUCT(Exposures!$B$10:$K$10,B7:K7)
A8: 42471 | B8: 0.0013250424 | C8: 0.00093027352 | D8: -0.0099642253 | E8: 0.0011382607 | F8: -0.0071500463 | G8: -0.0019777605 | H8: 0.0014982457 | I8: -0.002053147 | J8: 0.0010992336 | K8: 0.0075749102 | L8: 0.0043578221 | M8: =SUMPRODUCT(Exposures!$B$6:$K$6,B8:K8) | N8: =IF(AND($A8>=DATE(2020,2,1),$A8<=DATE(2020,5,31)),$M8,"") | O8: =IF(AND($A8>=DATE(2022,1,1),$A8<=DATE(2022,10,31)),$M8,"") | P8: =IF(AND($A8>=DATE(2018,10,1),$A8<=DATE(2018,12,31)),$M8,"") | Q8: =SUMPRODUCT(Exposures!$B$8:$K$8,B8:K8) | R8: =SUMPRODUCT(Exposures!$B$9:$K$9,B8:K8) | S8: =SUMPRODUCT(Exposures!$B$10:$K$10,B8:K8)
A9: 42472 | B9: 0.00095727097 | C9: 0.00015429665 | D9: 0.016892034 | E9: 0.00044328716 | F9: 0.0022724228 | G9: 0.0075175332 | H9: -0.0038326646 | I9: -0.0013904818 | J9: -0.00029467814 | K9: 0.0012434234 | L9: 0.0017820611 | M9: =SUMPRODUCT(Exposures!$B$6:$K$6,B9:K9) | N9: =IF(AND($A9>=DATE(2020,2,1),$A9<=DATE(2020,5,31)),$M9,"") | O9: =IF(AND($A9>=DATE(2022,1,1),$A9<=DATE(2022,10,31)),$M9,"") | P9: =IF(AND($A9>=DATE(2018,10,1),$A9<=DATE(2018,12,31)),$M9,"") | Q9: =SUMPRODUCT(Exposures!$B$8:$K$8,B9:K9) | R9: =SUMPRODUCT(Exposures!$B$9:$K$9,B9:K9) | S9: =SUMPRODUCT(Exposures!$B$10:$K$10,B9:K9)
A10: 42473 | B10: 0.011994379 | C10: 0.00035373928 | D10: -0.018817736 | E10: 0.0012741294 | F10: -5.8566686e-05 | G10: 0.018260822 | H10: -0.0038257126 | I10: -0.0023318944 | J10: -0.0015694175 | K10: -0.0033253299 | L10: 0.0028653987 | M10: =SUMPRODUCT(Exposures!$B$6:$K$6,B10:K10) | N10: =IF(AND($A10>=DATE(2020,2,1),$A10<=DATE(2020,5,31)),$M10,"") | O10: =IF(AND($A10>=DATE(2022,1,1),$A10<=DATE(2022,10,31)),$M10,"") | P10: =IF(AND($A10>=DATE(2018,10,1),$A10<=DATE(2018,12,31)),$M10,"") | Q10: =SUMPRODUCT(Exposures!$B$8:$K$8,B10:K10) | R10: =SUMPRODUCT(Exposures!$B$9:$K$9,B10:K10) | S10: =SUMPRODUCT(Exposures!$B$10:$K$10,B10:K10)
A11: 42474 | B11: 0.0012396972 | C11: -0.0019290679 | D11: 0.012929868 | E11: 0.0020212098 | F11: 0.0081196804 | G11: 0.0010068779 | H11: -0.0036546312 | I11: 0.0027632267 | J11: -0.0026777448 | K11: -0.0090936705 | L11: 0.00058150207 | M11: =SUMPRODUCT(Exposures!$B$6:$K$6,B11:K11) | N11: =IF(AND($A11>=DATE(2020,2,1),$A11<=DATE(2020,5,31)),$M11,"") | O11: =IF(AND($A11>=DATE(2022,1,1),$A11<=DATE(2022,10,31)),$M11,"") | P11: =IF(AND($A11>=DATE(2018,10,1),$A11<=DATE(2018,12,31)),$M11,"") | Q11: =SUMPRODUCT(Exposures!$B$8:$K$8,B11:K11) | R11: =SUMPRODUCT(Exposures!$B$9:$K$9,B11:K11) | S11: =SUMPRODUCT(Exposures!$B$10:$K$10,B11:K11)
A12: 42475 | B12: -0.0019377894 | C12: 0.00079193076 | D12: -0.0022715453 | E12: 0.00093113069 | F12: -0.0013294795 | G12: 0.0016827817 | H12: 0.00348522 | I12: -0.0001685023 | J12: 0.001358178 | K12: -0.0010787599 | L12: -0.0005217231 | M12: =SUMPRODUCT(Exposures!$B$6:$K$6,B12:K12) | N12: =IF(AND($A12>=DATE(2020,2,1),$A12<=DATE(2020,5,31)),$M12,"") | O12: =IF(AND($A12>=DATE(2022,1,1),$A12<=DATE(2022,10,31)),$M12,"") | P12: =IF(AND($A12>=DATE(2018,10,1),$A12<=DATE(2018,12,31)),$M12,"") | Q12: =SUMPRODUCT(Exposures!$B$8:$K$8,B12:K12) | R12: =SUMPRODUCT(Exposures!$B$9:$K$9,B12:K12) | S12: =SUMPRODUCT(Exposures!$B$10:$K$10,B12:K12)
A13: 42478 | B13: 0.0029358601 | C13: 0.00038888377 | D13: 0.041719105 | E13: -0.00043619923 | F13: -0.003080091 | G13: 0.0057506288 | H13: 0.0016177133 | I13: -0.00012763923 | J13: -0.00057413805 | K13: 0.0021005108 | L13: 0.00029286873 | M13: =SUMPRODUCT(Exposures!$B$6:$K$6,B13:K13) | N13: =IF(AND($A13>=DATE(2020,2,1),$A13<=DATE(2020,5,31)),$M13,"") | O13: =IF(AND($A13>=DATE(2022,1,1),$A13<=DATE(2022,10,31)),$M13,"") | P13: =IF(AND($A13>=DATE(2018,10,1),$A13<=DATE(2018,12,31)),$M13,"") | Q13: =SUMPRODUCT(Exposures!$B$8:$K$8,B13:K13) | R13: =SUMPRODUCT(Exposures!$B$9:$K$9,B13:K13) | S13: =SUMPRODUCT(Exposures!$B$10:$K$10,B13:K13)
... A2204: 45657 | B2204: -0.0031439249 | C2204: 0.00097399327 | D2204: -0.0014459892 | E2204: 0.00021290256 | F2204: -0.005618694 | G2204: 0.0029611701 | H2204: -0.004615006 | I2204: 0.0010980871 | J2204: 0.0015515437 | K2204: 0.0024756141 | L2204: 0.0017282913 | M2204: =SUMPRODUCT(Exposures!$B$6:$K$6,B2204:K2204) | N2204: =IF(AND($A2204>=DATE(2020,2,1),$A2204<=DATE(2020,5,31)),$M2204,"") | O2204: =IF(AND($A2204>=DATE(2022,1,1),$A2204<=DATE(2022,10,31)),$M2204,"") | P2204: =IF(AND($A2204>=DATE(2018,10,1),$A2204<=DATE(2018,12,31)),$M2204,"") | Q2204: =SUMPRODUCT(Exposures!$B$8:$K$8,B2204:K2204) | R2204: =SUMPRODUCT(Exposures!$B$9:$K$9,B2204:K2204) | S2204: =SUMPRODUCT(Exposures!$B$10:$K$10,B2204:K2204)

Sheet Risk
B1: Beta | C1: EarnYield | D1: Growth | E1: Leverage | F1: Liquidity | G1: Market | H1: Momentum | I1: NonLinSize | J1: ResidVol | K1: Size | L1: Value
A2: Factor vol σ (STDEV) | B2: =STDEV(FactorReturns!B2:B2204) | C2: =STDEV(FactorReturns!C2:C2204) | D2: =STDEV(FactorReturns!D2:D2204) | E2: =STDEV(FactorReturns!E2:E2204) | F2: =STDEV(FactorReturns!F2:F2204) | G2: =STDEV(FactorReturns!G2:G2204) | H2: =STDEV(FactorReturns!H2:H2204) | I2: =STDEV(FactorReturns!I2:I2204) | ... L2: =STDEV(FactorReturns!L2:L2204)
A4: Hypo sigma shocks | M4: Shock PnL
A5: Hypo:ValueRotation | B5: 0 | C5: 0 | D5: 0 | E5: 0 | F5: 0 | G5: 0 | H5: -2 | I5: 0 | J5: 0 | K5: 0 | L5: 2 | M5: =SUMPRODUCT(Exposures!$B$6:$K$6,B5:K5,$B$2:$K$2)
A6: Hypo:RiskOff | B6: -2 | C6: 0 | D6: 0 | E6: 0 | F6: 0 | G6: 0 | H6: 1 | I6: 0 | J6: 2 | K6: 0 | L6: 0 | M6: =SUMPRODUCT(Exposures!$B$6:$K$6,B6:K6,$B$2:$K$2)
A7: Hypo:MomentumCrash | B7: 0 | C7: 0 | D7: 0 | E7: 0 | F7: 0 | G7: 0 | H7: -3 | I7: 0 | J7: 0 | K7: 0 | L7: 0 | M7: =SUMPRODUCT(Exposures!$B$6:$K$6,B7:K7,$B$2:$K$2)
A10: ScenarioSet | B10: VaR 99 | C10: Worst loss | D10: Mean PnL | E10: Total VaR 99 | F10: VaR 99 (ref) | G10: Worst (ref) | H10: Mean (ref)
A11: HistFull | B11: =-PERCENTILE(FactorReturns!$M$2:$M$2204,0.01) | C11: =-MIN(FactorReturns!$M$2:$M$2204) | D11: =AVERAGE(FactorReturns!$M$2:$M$2204) | E11: =SQRT(B11^2+(2.326*$B$21)^2) | F11: 0.021507708 | G11: 0.050425664 | H11: 7.8109366e-05
A12: Evt:COVID2020 | B12: =-PERCENTILE(FactorReturns!$N$2:$N$2204,0.01) | C12: =-MIN(FactorReturns!$N$2:$N$2204) | D12: =AVERAGE(FactorReturns!$N$2:$N$2204) | E12: =SQRT(B12^2+(2.326*$B$21)^2) | F12: 0.040610756 | G12: 0.050425664 | H12: 0.00082887108
A13: Evt:Rates2022 | B13: =-PERCENTILE(FactorReturns!$O$2:$O$2204,0.01) | C13: =-MIN(FactorReturns!$O$2:$O$2204) | D13: =AVERAGE(FactorReturns!$O$2:$O$2204) | E13: =SQRT(B13^2+(2.326*$B$21)^2) | F13: 0.02494649 | G13: 0.030185259 | H13: -0.00077104076
A14: Evt:Selloff2018 | B14: =-PERCENTILE(FactorReturns!$P$2:$P$2204,0.01) | C14: =-MIN(FactorReturns!$P$2:$P$2204) | D14: =AVERAGE(FactorReturns!$P$2:$P$2204) | E14: =SQRT(B14^2+(2.326*$B$21)^2) | F14: 0.017321714 | G14: 0.022026905 | H14: -0.00080594817
A15: Hypo:ValueRotation | B15: =-M5 | C15: =-M5 | D15: =M5 | E15: =SQRT(B15^2+(2.326*$B$21)^2) | F15: 0.00043873222 | G15: 0.00043873222 | H15: -0.00043873222
A16: Hypo:RiskOff | B16: =-M6 | C16: =-M6 | D16: =M6 | E16: =SQRT(B16^2+(2.326*$B$21)^2) | F16: 0.00088815618 | G16: 0.00088815618 | H16: -0.00088815618
A17: Hypo:MomentumCrash | B17: =-M7 | C17: =-M7 | D17: =M7 | E17: =SQRT(B17^2+(2.326*$B$21)^2) | F17: 0.00035471319 | G17: 0.00035471319 | H17: -0.00035471319
A20: Specific variance Σw²σ² | B20: =SUMPRODUCT(Inputs!$D$4:$D$6*Inputs!$D$4:$D$6,Inputs!$E$4:$E$6) | C20: 2.498511e-05 | D20: (col C = pandas reference)
A21: Specific vol | B21: =SQRT(B20) | C21: 0.0049985107
A22: Per-issuer standalone risk — HistFull (name at its book weight)
A23: Issuer | B23: VaR 99 | C23: Worst loss | D23: Mean PnL | E23: Specific vol | F23: Total VaR 99 | G23: VaR 99 (ref) | H23: Worst (ref) | I23: Mean (ref) | J23: Spec vol (ref) | K23: Total VaR (ref)
A24: Alibaba Group Holding Ltd | B24: =-PERCENTILE(FactorReturns!$Q$2:$Q$2204,0.01) | C24: =-MIN(FactorReturns!$Q$2:$Q$2204) | D24: =AVERAGE(FactorReturns!$Q$2:$Q$2204) | E24: =SQRT(Inputs!$D$4^2*Inputs!$E$4) | F24: =SQRT(B24^2+(2.326*E24)^2) | G24: 0.010853201 | H24: 0.025321254 | I24: -1.6054706e-05 | J24: 0.0045232783 | K24: 0.015115769
A25: Alphabet Inc. | B25: =-PERCENTILE(FactorReturns!$R$2:$R$2204,0.01) | C25: =-MIN(FactorReturns!$R$2:$R$2204) | D25: =AVERAGE(FactorReturns!$R$2:$R$2204) | E25: =SQRT(Inputs!$D$5^2*Inputs!$E$5) | F25: =SQRT(B25^2+(2.326*E25)^2) | G25: 0.0068366338 | H25: 0.015007287 | I25: 4.6392689e-05 | J25: 0.001744433 | K25: 0.0079500493
A26: AMAZON COM INC | B26: =-PERCENTILE(FactorReturns!$S$2:$S$2204,0.01) | C26: =-MIN(FactorReturns!$S$2:$S$2204) | D26: =AVERAGE(FactorReturns!$S$2:$S$2204) | E26: =SQRT(Inputs!$D$6^2*Inputs!$E$6) | F26: =SQRT(B26^2+(2.326*E26)^2) | G26: 0.0045241518 | H26: 0.010097123 | I26: 4.7771383e-05 | J26: 0.0012173808 | K26: 0.0053372339
A28: Risk contributions to Scenario VaR 99 — HistFull (additive; Σ = book VaR) | D28: (cols F–H = pandas reference; t* = 1% VaR scenario)
A29: VaR scenario rank (k-th worst) | B29: 23
A30: Book P&L at scenario t* | B30: =SMALL(FactorReturns!$L$2:$L$2204,B29)
A31: Scenario position (MATCH) | B31: =MATCH(B30,FactorReturns!$L$2:$L$2204,0)
A32: Scenario date | B32: =INDEX(FactorReturns!$A$2:$A$2204,B31)
A34: Factor contributions
A35: Factor | B35: Net exp | C35: Component VaR | D35: Marginal VaR | E35: % of VaR | F35: Comp (ref) | G35: Marg (ref) | H35: % (ref)
A36: Beta | B36: =Exposures!B$6 | C36: =-(Exposures!B$6)*(INDEX(FactorReturns!$B$2:$B$2204,$B$31)) | D36: =C36/B36 | E36: =C36/$B$11 | F36: -0.00010126172 | G36: 0.019635181 | H36: -0.0047081594
A37: EarnYield | B37: =Exposures!C$6 | C37: =-(Exposures!C$6)*(INDEX(FactorReturns!$C$2:$C$2204,$B$31)) | D37: =C37/B37 | E37: =C37/$B$11 | F37: 0.0015257928 | G37: 0.005507855 | H37: 0.070941671
A38: Growth | B38: =Exposures!D$6 | C38: =-(Exposures!D$6)*(INDEX(FactorReturns!$D$2:$D$2204,$B$31)) | D38: =C38/B38 | E38: =C38/$B$11 | F38: 0 | H38: 0
A39: Leverage | B39: =Exposures!E$6 | C39: =-(Exposures!E$6)*(INDEX(FactorReturns!$E$2:$E$2204,$B$31)) | D39: =C39/B39 | E39: =C39/$B$11 | F39: 0.00056635554 | G39: -0.0019312944 | H39: 0.026332677
A40: Liquidity | B40: =Exposures!F$6 | C40: =-(Exposures!F$6)*(INDEX(FactorReturns!$F$2:$F$2204,$B$31)) | D40: =C40/B40 | E40: =C40/$B$11 | F40: -0.01157923 | G40: -0.010974495 | H40: -0.53837582
A41: Market | B41: =Exposures!G$6 | C41: =-(Exposures!G$6)*(INDEX(FactorReturns!$G$2:$G$2204,$B$31)) | D41: =C41/B41 | E41: =C41/$B$11 | F41: 0.020861165 | G41: 0.040628297 | H41: 0.96993897
A42: Momentum | B42: =Exposures!H$6 | C42: =-(Exposures!H$6)*(INDEX(FactorReturns!$H$2:$H$2204,$B$31)) | D42: =C42/B42 | E42: =C42/$B$11 | F42: -0.00013771112 | G42: -0.0048684715 | H42: -0.0064028729
A43: NonLinSize | B43: =Exposures!I$6 | C43: =-(Exposures!I$6)*(INDEX(FactorReturns!$I$2:$I$2204,$B$31)) | D43: =C43/B43 | E43: =C43/$B$11 | F43: -0.0013382109 | G43: 0.0020353261 | H43: -0.062220058
A44: ResidVol | B44: =Exposures!J$6 | C44: =-(Exposures!J$6)*(INDEX(FactorReturns!$J$2:$J$2204,$B$31)) | D44: =C44/B44 | E44: =C44/$B$11 | F44: -0.00085820998 | G44: 0.0073165463 | H44: -0.039902437
A45: Size | B45: =Exposures!K$6 | C45: =-(Exposures!K$6)*(INDEX(FactorReturns!$K$2:$K$2204,$B$31)) | D45: =C45/B45 | E45: =C45/$B$11 | F45: 0.012446576 | G45: 0.0091736766 | H45: 0.57870303
A46: Value | B46: =Exposures!L$6 | C46: =-(Exposures!L$6)*(INDEX(FactorReturns!$L$2:$L$2204,$B$31)) | D46: =C46/B46 | E46: =C46/$B$11 | F46: 0.00013298739 | G46: -0.0033526717 | H46: 0.0061832433
A47: Σ (= Scenario VaR 99) | C47: =SUM(C36:C46) | E47: =SUM(E36:E46)
...
